Workbook

Sheet Admin
A2: Relocation fee???
H7: basic/PMI Bronze has 10% discount
A8: Service and Parts | B8: TS email, contract matters for discount
A9: Move | B9: contract doesn't matter
A10: Parts ONLY | B10: orders email, contract matters for discount
H11: protection on cells - turn into API
C15: Contract pricing - service
C16: Contract | D16: ='FSE Input'!B13 -> #REF! | E16: labor? | F16: cost | G16: premium contract | H16: 20% discount | I16: 10% dicsount | J16: final price
C17: part 1 | D17: =IF('FSE Input'!B17<>"",'FSE Input'!B17,IF('FSE Input'!B21<>"",'FSE Input'!B21,"")) -> On-Site Support (2 days) | E17: =IF(OR(ISNUMBER(SEARCH("site",D17)),ISNUMBER(SEARCH("service",D17)),ISNUMBER(SEARCH("support",D17))),"Yes","No") -> Yes | F17: =IF('FSE Input'!B19<>"",'FSE Input'!B19,IF('FSE Input'!B23<>"",'FSE Input'!B23,"")) -> 7571 | G17: =IF(E17="Yes", F17, IF(OR($D$16="Premium", $D$16="Gold", ISNUMBER(SEARCH("COMPLET",$D$16))), F17, "")) -> 7571 | H17: =IF(E17="Yes", F17, IF(OR($D$16="VALUE", $D$16="Silver", ISNUMBER(SEARCH("INTERMED",$D$16))), F17*0.8, "")) -> 7571 | I17: =IF(E17="Yes", F17, IF(OR($D$16="PMI", $D$16="Bronze", ISNUMBER(SEARCH("BASIC",$D$16))), F17*0.9, "")) -> 7571 | J17: =IF(E17="Yes", F17, IF(OR($D$16="Premium", $D$16="Gold", ISNUMBER(SEARCH("COMPLET",$D$16))), F17, IF(OR($D$16="VALUE", $D$16="Silver", ISNUMBER(SEARCH("INTERMED",$D$16))), F17*0.8, IF(OR($D$16="PMI", $D$16="Bronze", ISNUMBER(SEARCH("BASIC",$D$16))), F17*0.9, "" ) ) ) ) -> 7571
C18: part 2 | D18: =IF('FSE Input'!B25<>"",'FSE Input'!B25,IF('FSE Input'!B29<>"",'FSE Input'!B29,"")) | E18: =IF(OR(ISNUMBER(SEARCH("site",D18)),ISNUMBER(SEARCH("service",D18)),ISNUMBER(SEARCH("support",D18))),"Yes","No") -> No | F18: =IF('FSE Input'!B27<>"",'FSE Input'!B27,IF('FSE Input'!B31<>"",'FSE Input'!B31,"")) | G18: =IF(E18="Yes", F18, IF(OR($D$16="Premium", $D$16="Gold", ISNUMBER(SEARCH("COMPLET",$D$16))), F18, "")) -> #REF! | H18: =IF(E18="Yes", F18, IF(OR($D$16="VALUE", $D$16="Silver", ISNUMBER(SEARCH("INTERMED",$D$16))), F18*0.8, "")) -> #REF! | I18: =IF(E18="Yes", F18, IF(OR($D$16="PMI", $D$16="Bronze", ISNUMBER(SEARCH("BASIC",$D$16))), F18*0.9, "")) -> #REF! | J18: =IF(E18="Yes", F18, IF(OR($D$16="Premium", $D$16="Gold", ISNUMBER(SEARCH("COMPLET",$D$16))), F18, IF(OR($D$16="VALUE", $D$16="Silver", ISNUMBER(SEARCH("INTERMED",$D$16))), F18*0.8, IF(OR($D$16="PMI", $D$16="Bronze", ISNUMBER(SEARCH("BASIC",$D$16))), F18*0.9, "" ) ) ) ) -> #REF!
C19: part 3 | D19: =IF('FSE Input'!B33<>"",'FSE Input'!B33,IF('FSE Input'!B37<>"",'FSE Input'!B37,"")) | E19: =IF(OR(ISNUMBER(SEARCH("site",D19)),ISNUMBER(SEARCH("service",D19)),ISNUMBER(SEARCH("support",D19))),"Yes","No") -> No | F19: =IF('FSE Input'!B35<>"",'FSE Input'!B35,IF('FSE Input'!B39<>"",'FSE Input'!B39,"")) | G19: =IF(E19="Yes", F19, IF(OR($D$16="Premium", $D$16="Gold", ISNUMBER(SEARCH("COMPLET",$D$16))), F19, "")) -> #REF! | H19: =IF(E19="Yes", "", IF(OR($D$16="VALUE", $D$16="Silver", ISNUMBER(SEARCH("INTERMED",$D$16))), F19*0.8, "")) -> #REF! | I19: =IF(E19="Yes", F19, IF(OR($D$16="PMI", $D$16="Bronze", ISNUMBER(SEARCH("BASIC",$D$16))), F19*0.9, "")) -> #REF! | J19: =IF(E19="Yes", F19, IF(OR($D$16="Premium", $D$16="Gold", ISNUMBER(SEARCH("COMPLET",$D$16))), F19, IF(OR($D$16="VALUE", $D$16="Silver", ISNUMBER(SEARCH("INTERMED",$D$16))), F19*0.8, IF(OR($D$16="PMI", $D$16="Bronze", ISNUMBER(SEARCH("BASIC",$D$16))), F19*0.9, "" ) ) ) ) -> #REF!
C20: part 4 | D20: =IF('FSE Input'!B41<>"",'FSE Input'!B41,IF('FSE Input'!B45<>"",'FSE Input'!B45,"")) | E20: =IF(OR(ISNUMBER(SEARCH("site",D20)),ISNUMBER(SEARCH("service",D20)),ISNUMBER(SEARCH("support",D20))),"Yes","No") -> No | F20: =IF('FSE Input'!B43<>"",'FSE Input'!B43,IF('FSE Input'!B47<>"",'FSE Input'!B47,"")) | G20: =IF(E20="Yes", F20, IF(OR($D$16="Premium", $D$16="Gold", ISNUMBER(SEARCH("COMPLET",$D$16))), F20, "")) -> #REF! | H20: =IF(E20="Yes", F20, IF(OR($D$16="VALUE", $D$16="Silver", ISNUMBER(SEARCH("INTERMED",$D$16))), F20*0.8, "")) -> #REF! | I20: =IF(E20="Yes", F20, IF(OR($D$16="PMI", $D$16="Bronze", ISNUMBER(SEARCH("BASIC",$D$16))), F20*0.9, "")) -> #REF! | J20: =IF(E20="Yes", F20, IF(OR($D$16="Premium", $D$16="Gold", ISNUMBER(SEARCH("COMPLET",$D$16))), F20, IF(OR($D$16="VALUE", $D$16="Silver", ISNUMBER(SEARCH("INTERMED",$D$16))), F20*0.8, IF(OR($D$16="PMI", $D$16="Bronze", ISNUMBER(SEARCH("BASIC",$D$16))), F20*0.9, "" ) ) ) ) -> #REF!
C22: contract pricing - parts
C23: contract | D23: ='FSE Input'!E13 -> #REF! | E23: labor? | F23: cost | G23: premium | H23: 20% discount | I23: 10% discount | J23: final price
C24: part 1 | D24: =IF('FSE Input'!E17<>"",'FSE Input'!E17,IF('FSE Input'!E21<>"",'FSE Input'!E21,"")) -> On-Site Support (2 days) | E24: =IF(OR(ISNUMBER(SEARCH("site",D24)),ISNUMBER(SEARCH("service",D24)),ISNUMBER(SEARCH("support",D24))),"Yes","No") -> Yes | F24: =IF('FSE Input'!E19<>"",'FSE Input'!E19,IF('FSE Input'!E23<>"",'FSE Input'!E23,"")) -> 7571 | G24: =IF(E24="Yes", F24, IF(OR($D$23="Premium", $D$23="Gold", ISNUMBER(SEARCH("COMPLET",$D$23))), F24, "")) -> 7571 | H24: =IF(E24="Yes", F24, IF(OR($D$23="VALUE", $D$23="Silver", ISNUMBER(SEARCH("INTERMED",$D$23))), F24*0.8, "")) -> 7571 | I24: =IF(E24="Yes", F24, IF(OR($D$23="PMI", $D$23="Bronze", ISNUMBER(SEARCH("BASIC",$D$23))), F24*0.9, "")) -> 7571 | J24: =IF(E24="Yes", F24, IF(OR($D$23="Premium", $D$23="Gold", ISNUMBER(SEARCH("COMPLET",$D$23))), F24, IF(OR($D$23="VALUE", $D$23="Silver", ISNUMBER(SEARCH("INTERMED",$D$23))), F24*0.8, IF(OR($D$23="PMI", $D$23="Bronze", ISNUMBER(SEARCH("BASIC",$D$23))), F24*0.9, "" ) ) ) ) -> 7571
C25: part 2 | D25: =IF('FSE Input'!E25<>"",'FSE Input'!E25,IF('FSE Input'!E29<>"",'FSE Input'!E29,"")) -> Flow Cell Body | E25: =IF(OR(ISNUMBER(SEARCH("site",D25)),ISNUMBER(SEARCH("service",D25)),ISNUMBER(SEARCH("support",D25))),"Yes","No") -> No | F25: =IF('FSE Input'!E27<>"",'FSE Input'!E27,IF('FSE Input'!E31<>"",'FSE Input'!E31,"")) -> 268.71 | G25: =IF(E25="Yes", F25, IF(OR($D$23="Premium", $D$16="Gold", ISNUMBER(SEARCH("COMPLET",$D$23))), F25, "")) -> #REF! | H25: =IF(E25="Yes", F25, IF(OR($D$23="VALUE", $D$23="Silver", ISNUMBER(SEARCH("INTERMED",$D$23))), F25*0.8, "")) -> #REF! | I25: =IF(E25="Yes", F25, IF(OR($D$16="PMI", $D$16="Bronze", ISNUMBER(SEARCH("BASIC",$D$16))), F25*0.9, "")) -> #REF! | J25: =IF(E25="Yes", F25, IF(OR($D$23="Premium", $D$23="Gold", ISNUMBER(SEARCH("COMPLET",$D$23))), F25, IF(OR($D$23="VALUE", $D$23="Silver", ISNUMBER(SEARCH("INTERMED",$D$23))), F25*0.8, IF(OR($D$23="PMI", $D$23="Bronze", ISNUMBER(SEARCH("BASIC",$D$23))), F25*0.9, "" ) ) ) ) -> #REF!
C26: part 3 | D26: =IF('FSE Input'!E33<>"",'FSE Input'!E33,IF('FSE Input'!E37<>"",'FSE Input'!E37,"")) -> Mounting Plate | E26: =IF(OR(ISNUMBER(SEARCH("site",D26)),ISNUMBER(SEARCH("service",D26)),ISNUMBER(SEARCH("support",D26))),"Yes","No") -> No | F26: =IF('FSE Input'!E35<>"",'FSE Input'!E35,IF('FSE Input'!E39<>"",'FSE Input'!E39,"")) -> 7.76 | G26: =IF(E26="Yes", F26, IF(OR($D$23="Premium", $D$23="Gold", ISNUMBER(SEARCH("COMPLET",$D$23))), F26, "")) -> #REF! | H26: =IF(E26="Yes", "", IF(OR($D$23="VALUE", $D$23="Silver", ISNUMBER(SEARCH("INTERMED",$D$23))), F26*0.8, "")) -> #REF! | I26: =IF(E26="Yes", F26, IF(OR($D$16="PMI", $D$16="Bronze", ISNUMBER(SEARCH("BASIC",$D$16))), F26*0.9, "")) -> #REF! | J26: =IF(E26="Yes", F26, IF(OR($D$23="Premium", $D$23="Gold", ISNUMBER(SEARCH("COMPLET",$D$23))), F26, IF(OR($D$23="VALUE", $D23="Silver", ISNUMBER(SEARCH("INTERMED",$D$23))), F26*0.8, IF(OR($D$23="PMI", $D$23="Bronze", ISNUMBER(SEARCH("BASIC",$D$23))), F26*0.9, "" ) ) ) ) -> #REF!
C27: part 4 | D27: =IF('FSE Input'!E41<>"",'FSE Input'!E41,IF('FSE Input'!E45<>"",'FSE Input'!E45,"")) -> generator | E27: =IF(OR(ISNUMBER(SEARCH("site",D27)),ISNUMBER(SEARCH("service",D27)),ISNUMBER(SEARCH("support",D27))),"Yes","No") -> No | F27: =IF('FSE Input'!E43<>"",'FSE Input'!E43,IF('FSE Input'!E47<>"",'FSE Input'!E47,"")) -> 800 | G27: =IF(E27="Yes", F27, IF(OR($D$23="Premium", $D$23="Gold", ISNUMBER(SEARCH("COMPLET",$D$23))), F27, "")) -> #REF! | H27: =IF(E27="Yes", F27, IF(OR($D$23="VALUE", $D$23="Silver", ISNUMBER(SEARCH("INTERMED",$D$23))), F27*0.8, "")) -> #REF! | I27: =IF(E27="Yes", F27, IF(OR($D$16="PMI", $D$16="Bronze", ISNUMBER(SEARCH("BASIC",$D$16))), F27*0.9, "")) -> #REF! | J27: =IF(E27="Yes", F27, IF(OR($D$23="Premium", $D$23="Gold", ISNUMBER(SEARCH("COMPLET",$D$23))), F27, IF(OR($D$23="VALUE", $D$23="Silver", ISNUMBER(SEARCH("INTERMED",$D$23))), F27*0.8, IF(OR($D$23="PMI", $D$23="Bronze", ISNUMBER(SEARCH("BASIC",$D$23))), F27*0.9, "" ) ) ) ) -> #REF!
D34: need to include the if not listed here | F34: test if all work for if not listed
D35: note
D36: add a little popup that says if the contract is value, amke sure this is not the customer's first repair if so no quote needed
D37: how to do pricing? which cell has numbers? or combine everything into one

Sheet FSE Input
A1: What are you quoting?
A2: Service and Parts
A6: Use "Cytek Service Quoting" Tab to print quote | D6: Use "Cytek Parts Quoting" Tab to print quote
A7: CUSTOMER INFORMATION - SERVICE QUOTE | D7: Customer information - Parts Quote
A8: Name of customer requesting service/part: | B8: Alyssa Sanfillipo | D8: Name of customer requesting service/part: | E8: Mike Waring
A9: Instrument SN: | B9: R0732 | D9: Instrument SN: | E9: U1399
A10: Facility name: | B10: =VLOOKUP(B9,#REF!,2,FALSE) -> #REF! | D10: Facility name: | E10: =VLOOKUP(E9,#REF!,2,FALSE) -> #REF!
A11: Shortened Facility name | B11: =VLOOKUP(B10,#REF!,2,FALSE) -> #REF! | D11: Shortened Facility name | E11: =VLOOKUP(E10,#REF!,2,FALSE) -> #REF!
A12: Facility Address: | B12: =VLOOKUP(B9,#REF!,19,FALSE) -> #REF! | D12: Facility Address: | E12: =VLOOKUP(E9,#REF!,19,FALSE) -> #REF!
A13: Contract type: | B13: =VLOOKUP(B9,#REF!,9,FALSE) -> #REF! | D13: Contract type: | E13: =VLOOKUP(E9,#REF!,9,FALSE) -> #REF!
A15: SERVICE TYPE/PART NAME - SERVICE QUOTE | D15: SERVICE TYPE/PART NAME - PARTS QUOTE
A16: PART 1 | D16: PART 1
A17: Service Type/ Part Name | B17: On-Site Support (2 days) | D17: Service Type/ Part Name | E17: On-Site Support (2 days)
A18: Service Type/Part Number | B18: =IF(B17="","",VLOOKUP(B17,'Pricing Data'!A$2:H5436,7,FALSE)) -> 60020 | D18: Service Type/Part Number | E18: =IF(E17="","",VLOOKUP(E17,'Pricing Data'!A$2:H5436,7,FALSE)) -> 60020
A19: Service Type/ Part Price | B19: =IF(B17="","",VLOOKUP(B17,'Pricing Data'!A$2:H5436,4,FALSE)) -> 7571 | D19: Service Type/ Part Price | E19: =IF(E17="","",VLOOKUP(E17,'Pricing Data'!A$2:H5436,4,FALSE)) -> 7571
A20: Quantity | B20: 1 | D20: Quantity | E20: 1
A21: Service Type / Part Name (if not listed) | D21: Service Type / Part Name (if not listed)
A22: Service Type Part Number (if not listed) | D22: Service Type Part Number (if not listed)
A23: Price of Service Type / Part (if not listed) | D23: Price of Service Type / Part (if not listed)
A24: PART 2 | D24: PART 2
A25: Service Type/ Part Name | D25: Service Type/ Part Name | E25: Flow Cell Body
A26: Service Type/Part Number | B26: =IF(B25="","",VLOOKUP(B25,'Pricing Data'!A$2:H5436,7,FALSE)) | D26: Service Type/Part Number | E26: =IF(E25="","",VLOOKUP(E25,'Pricing Data'!A$2:H5444,7,FALSE)) -> N0-00011
A27: Service Type/ Part Price | B27: =IF(B25="","",VLOOKUP(B25,'Pricing Data'!A$2:H5436,4,FALSE)) | D27: Service Type/ Part Price | E27: =IF(E25="","",VLOOKUP(E25,'Pricing Data'!A$2:H5444,4,FALSE)) -> 268.71
A28: Quantity | D28: Quantity | E28: 1
A29: Service Type / Part Name (if not listed) | D29: Service Type / Part Name (if not listed)
A30: Service Type Part Number (if not listed) | D30: Service Type Part Number (if not listed)
A31: Price of Service Type / Part (if not listed) | D31: Price of Service Type / Part (if not listed)
A32: PART 3 | D32: PART 3
A33: Service Type/ Part Name | D33: Service Type/ Part Name | E33: Mounting Plate
A34: Service Type/Part Number | B34: =IF(B33="","",VLOOKUP(B33,'Pricing Data'!A$2:H5436,7,FALSE)) | D34: Service Type/Part Number | E34: =IF(E33="","",VLOOKUP(E33,'Pricing Data'!A$2:H5452,7,FALSE)) -> N0-00002
A35: Service Type/ Part Price | B35: =IF(B33="","",VLOOKUP(B33,'Pricing Data'!A$2:H5436,4,FALSE)) | D35: Service Type/ Part Price | E35: =IF(E33="","",VLOOKUP(E33,'Pricing Data'!A$2:H5452,4,FALSE)) -> 7.76
A36: Quantity | D36: Quantity | E36: 1
A37: Service Type / Part Name (if not listed) | D37: Service Type / Part Name (if not listed)
A38: Service Type Part Number (if not listed) | D38: Service Type Part Number (if not listed)
A39: Price of Service Type / Part (if not listed) | D39: Price of Service Type / Part (if not listed)
A40: PART 4 | D40: PART 4
A41: Service Type/ Part Name | D41: Service Type/ Part Name
A42: Service Type/Part Number | B42: =IF(B41="","",VLOOKUP(B41,'Pricing Data'!A$2:H5436,7,FALSE)) | D42: Service Type/Part Number | E42: =IF(E41="","",VLOOKUP(E41,'Pricing Data'!A$2:H5460,7,FALSE))
A43: Service Type/ Part Price | B43: =IF(B41="","",VLOOKUP(B41,'Pricing Data'!A$2:H5436,4,FALSE)) | D43: Service Type/ Part Price | E43: =IF(E41="","",VLOOKUP(E41,'Pricing Data'!A$2:H5460,4,FALSE))
A44: Quantity | D44: Quantity | E44: 1
...

Sheet Cytek Service Quoting
C2: ='FSE Input'!B8 -> Alyssa Sanfillipo | F2: ="QUOTE#: "&'FSE Input'!$B$11&" "&'FSE Input'!$B$9 -> #REF!
C3: ='FSE Input'!B10 -> #REF!
C4: ='FSE Input'!B12 -> #REF!
C7: Item | D7: Description | E7: Product Number | F7: Qty | G7: List Price | H7: Net Price | I7: Ext. Price
C8: =IF(D8="", "", "1") -> 1 | D8: =IF('FSE Input'!B17<>"", 'FSE Input'!B17, IF('FSE Input'!B21<>"", 'FSE Input'!B21, "")) -> On-Site Support (2 days) | E8: =IF('FSE Input'!B18<>"", 'FSE Input'!B18, IF('FSE Input'!B22<>"", 'FSE Input'!B22, "")) -> 60020 | F8: =IF(ISBLANK('FSE Input'!B20),"",'FSE Input'!B20) -> 1 | G8: =IF('FSE Input'!B19<>"", 'FSE Input'!B19, IF('FSE Input'!B23<>"", 'FSE Input'!B23, "")) -> 7571 | H8: =IF(Admin!D17<>"",Admin!J17,"") -> 7571 | I8: =IF(G8="","",H8*F8) -> 7571
C9: =IF(D9="", "", "2") | D9: =IF('FSE Input'!B25<>"", 'FSE Input'!B25, IF('FSE Input'!B29<>"", 'FSE Input'!B29, "")) | E9: =IF('FSE Input'!B26<>"", 'FSE Input'!B26, IF('FSE Input'!B30<>"", 'FSE Input'!B30, "")) | F9: =IF(ISBLANK('FSE Input'!B28),"",'FSE Input'!B28) | G9: =IF('FSE Input'!B27<>"", 'FSE Input'!B27, IF('FSE Input'!B31<>"", 'FSE Input'!B31, "")) | H9: =IF(Admin!D18<>"",Admin!J18,"") | I9: =IF(G9="","",H9*F9)
C10: =IF(D10="", "", "3") | D10: =IF('FSE Input'!B33<>"", 'FSE Input'!B33, IF('FSE Input'!B37<>"", 'FSE Input'!B37, "")) | E10: =IF('FSE Input'!B34<>"", 'FSE Input'!B34, IF('FSE Input'!B38<>"", 'FSE Input'!B38, "")) | F10: =IF(ISBLANK('FSE Input'!B36),"",'FSE Input'!B36) | G10: =IF('FSE Input'!B35<>"", 'FSE Input'!B35, IF('FSE Input'!B39<>"", 'FSE Input'!B39, "")) | H10: =IF(Admin!D19<>"",Admin!J19,"") | I10: =IF(G10="","",H10*F10)
C11: =IF(D11="", "", "4") | D11: =IF('FSE Input'!B41<>"", 'FSE Input'!B41, IF('FSE Input'!B45<>"", 'FSE Input'!B45, "")) | E11: =IF('FSE Input'!B42<>"", 'FSE Input'!B42, IF('FSE Input'!B46<>"", 'FSE Input'!B46, "")) | F11: =IF(ISBLANK('FSE Input'!B44),"",'FSE Input'!B44) | G11: =IF('FSE Input'!B43<>"", 'FSE Input'!B43, IF('FSE Input'!B47<>"", 'FSE Input'!B47, "")) | H11: =IF(Admin!D20<>"",Admin!J20,"") | I11: =IF(G11="","",H11*F11)
C13: Shipping & Handling Estimate
C14: Total | I14: =SUM(I15,I8:I11) -> 7571
D16: Pre-Inspection/Recertification
G101: ="QUOTE#: "&'FSE Input Old'!$D$3&" "&'FSE Input Old'!$B$3 -> #REF!
G153: ="QUOTE#: "&'FSE Input Old'!$D$3&" "&'FSE Input Old'!$B$3 -> #REF!

Sheet Cytek Parts Quoting
C2: ='FSE Input'!E8 -> Mike Waring | F2: ="QUOTE#: "&'FSE Input'!$E$11&" "&'FSE Input'!$E$9 -> #REF!
C3: ='FSE Input'!E10 -> #REF!
C4: ='FSE Input'!E12 -> #REF!
C7: Item | D7: Description | E7: Product Number | F7: Qty | G7: List Price | H7: Net Price | I7: Ext. Price
C8: =IF(D8="", "", "1") -> 1 | D8: =IF('FSE Input'!E17<>"", 'FSE Input'!E17, IF('FSE Input'!E21<>"", 'FSE Input'!E21, "")) -> On-Site Support (2 days) | E8: =IF('FSE Input'!E18<>"", 'FSE Input'!E18, IF('FSE Input'!E22<>"", 'FSE Input'!E22, "")) -> 60020 | F8: =IF(ISBLANK('FSE Input'!E20),"",'FSE Input'!E20) -> 1 | G8: =IF('FSE Input'!E19<>"", 'FSE Input'!E19, IF('FSE Input'!E23<>"", 'FSE Input'!E23, "")) -> 7571 | H8: =IF(Admin!D24<>"",Admin!J24,"") -> 7571 | I8: =IF(G8="","",H8*F8) -> 7571
C9: =IF(D9="", "", "2") -> 2 | D9: =IF('FSE Input'!E25<>"", 'FSE Input'!E25, IF('FSE Input'!E29<>"", 'FSE Input'!E29, "")) -> Flow Cell Body | E9: =IF('FSE Input'!E26<>"", 'FSE Input'!E26, IF('FSE Input'!E30<>"", 'FSE Input'!E30, "")) -> N0-00011 | F9: =IF(ISBLANK('FSE Input'!E28),"",'FSE Input'!E28) -> 1 | G9: =IF('FSE Input'!E27<>"", 'FSE Input'!E27, IF('FSE Input'!E31<>"", 'FSE Input'!E31, "")) -> 268.71 | H9: =IF(Admin!D25<>"",Admin!J25,"") -> #REF! | I9: =IF(G9="","",H9*F9) -> #REF!
C10: =IF(D10="", "", "3") -> 3 | D10: =IF('FSE Input'!E33<>"", 'FSE Input'!E33, IF('FSE Input'!E37<>"", 'FSE Input'!E37, "")) -> Mounting Plate | E10: =IF('FSE Input'!E34<>"", 'FSE Input'!E34, IF('FSE Input'!E38<>"", 'FSE Input'!E38, "")) -> N0-00002 | F10: =IF(ISBLANK('FSE Input'!E36),"",'FSE Input'!E36) -> 1 | G10: =IF('FSE Input'!E35<>"", 'FSE Input'!E35, IF('FSE Input'!E39<>"", 'FSE Input'!E39, "")) -> 7.76 | H10: =IF(Admin!D26<>"",Admin!J26,"") -> #REF! | I10: =IF(G10="","",H10*F10) -> #REF!
C11: =IF(D11="", "", "4") -> 4 | D11: =IF('FSE Input'!E41<>"", 'FSE Input'!E41, IF('FSE Input'!E45<>"", 'FSE Input'!E45, "")) -> generator | E11: =IF('FSE Input'!E42<>"", 'FSE Input'!E42, IF('FSE Input'!E46<>"", 'FSE Input'!E46, "")) -> u1093 | F11: =IF(ISBLANK('FSE Input'!E44),"",'FSE Input'!E44) -> 1 | G11: =IF('FSE Input'!E43<>"", 'FSE Input'!E43, IF('FSE Input'!E47<>"", 'FSE Input'!E47, "")) -> 800 | H11: =IF(Admin!D27<>"",Admin!J27,"") -> #REF! | I11: =IF(G11="","",H11*F11) -> #REF!
C13: Shipping & Handling Estimate
C14: Total | I14: =SUM(I15,I8:I11) -> #REF!
G49: ="QUOTE#: "&'FSE Input Old'!$D$3&" "&'FSE Input Old'!$B$3 -> #REF!
G101: ="QUOTE#: "&'FSE Input Old'!$D$3&" "&'FSE Input Old'!$B$3 -> #REF!
G153: ="QUOTE#: "&'FSE Input Old'!$D$3&" "&'FSE Input Old'!$B$3 -> #REF!

Sheet Asset Data
A1: Product: Product Name | B1: Serial Number | C1: Install Date | D1: Synced Contract: Contract Number | E1: Status | F1: Account Name | G1: Synced Contract: Contract End Date | H1: Country | I1: Synced Contract: Contract Type
A2: Guava easyCyte 6-2L, Boxed Instrument | B2: 10000006001 | C2: 43369 | E2: Installed | F2: Institut Universitaire de Technologie (IUT) Louis Pasteur
A3: Guava PCA Base System, with software, Obsolete | B3: 1000880 | C3: 40407 | E3: Installed | F3: Shanxi Medical University????????
A4: Amnis ImageStreamX MkII System w/ INSPIRE & IDEAS Software | B4: 100220 | C4: 43217 | E4: Deinstalled | F4: FUWAI HOSPITAL
A5: xP4 Upgrade | B5: 1040 | C5: 38955 | E5: Installed | F5: Thermo Fisher Scientific - Life Technologies Corporation
A6: MUSE CELL ANALYZER SYSTEM | B6: 11 | C6: 41619 | E6: Installed | F6: QUALITY ASSISTANCE
A7: Guava PCA Base System, with software, Obsolete | B7: 1100900 | C7: 40842 | E7: Installed | F7: FIBROCELL SCIENCE INC
A8: MUSE CELL ANALYZER SYSTEM | B8: 11111-018838 | C8: 41855 | E8: Installed | F8: LPU GMBH
A9: xP4 Upgrade | B9: 1151 | C9: 40084 | E9: Installed | F9: University of Utah
A10: Automatic Micro-Sampler CE | B10: 1314 | C10: 40864 | E10: Installed | F10: TU Delft_microbiology
A11: xP4 Upgrade | B11: 1316 | C11: 40835 | E11: Installed | F11: Seattle Pacific University
A12: xP5 Upgrade | B12: 1343 | C12: 40928 | E12: Installed | F12: Aptevo Research and Development LLC
A13: xP5 Upgrade | B13: 1345 | C13: 40948 | E13: Installed | F13: Affymetrix
... A38: FlowKart | B38: 1516 | C38: 43277 | E38: Installed | F38: Regeneron Pharmaceuticals Inc
B39: 2800060146R | C39: 39052 | E39: Deinstalled | F39: ExcellGene SA
B40: 3630090414 | C40: 40014 | E40: Deinstalled | F40: REIN TX (PREV. AILERON THERAPEUTICS)
A41: Guava easyCyte 6-2L, Boxed Instrument | B41: 6620106007 | C41: 40492 | E41: Deinstalled | F41: NYU Langone Health
A42: Guava easyCyte 6-2L, Boxed Instrument | B42: 6620126046 | C42: 40970 | E42: Deinstalled | F42: Eberhard Karls Universität Tübingen
A43: Guava easyCyte 6-2L, Boxed Instrument | B43: 6620126092 | C43: 41373 | E43: Deinstalled | F43: Merck KGaA - Merck Biodevelopment SAS
A44: Guava easyCyte 8SL, Boxed Instrument | B44: 6620128023 | C44: 41297 | E44: Deinstalled | F44: AstraZeneca Pharmaceuticals LP - R&D Boston MA
B45: 662012S008 | C45: 40955 | E45: Installed | F45: FRAUNHOFER-INSTITUT FUR ZELLTHERAPIE UND IMMUNOLOGIE IZI
B46: 662012S015 | C46: 41353 | E46: Installed | F46: UK Health Security Agency
A47: Guava easyCyte 6-2L, Boxed Instrument | B47: 6620136106 | C47: 41439 | E47: Deinstalled | F47: Karlsruher Institut für Technologie
B48: 662013S017 | C48: 41338 | E48: Installed | F48: MRC Laboratory of Medical Sciences (LMS)
B49: 662013S020 | C49: 41540 | E49: Installed | F49: Hôpitaux Universitaires - Pitié Salpêtrière
A50: Guava easyCyte 5SL, Boxed Instrument | B50: 6620145182 | C50: 41921 | E50: Deinstalled | F50: Cook MyoSite Inc
B51: 662014S024 | C51: 41988 | E51: Installed | F51: Howard Hughes Medical Institute (HHMI)
B52: 6620-R6144 | C52: 42139 | E52: Deinstalled | F52: INTERTEK PHARMACEUTICALS
A53: Guava easyCyte 6HT-2L, Boxed Instrument | B53: 6735116035 | C53: 40721 | E53: Deinstalled | F53: Thermo Fisher Scientific - Guilford CT
A54: Guava easyCyte 8HT, Boxed Instrument | B54: 6735118079 | C54: 40925 | E54: Deinstalled | F54: Massachusetts Institute of Technology (MIT)
B55: 6735125108 | C55: 41395 | E55: Deinstalled | F55: University of Pittsburgh
B56: 6735125120 | C56: 41200 | E56: Deinstalled | F56: Millipore Sigma (formerly Mirius Bio LLC)
A57: Guava easyCyte 6HT-2L, Boxed Instrument | B57: 6735125124A | C57: 41793 | E57: Deinstalled | F57: BEIJING WANTAI BIOLOGICAL PHARMACY ENTERPRISE CO LTD
B58: 6735125136 | C58: 41281 | E58: Deinstalled | F58: IPSEN (PREVIOUSLY EPIZYME INC)
A59: Guava easyCyte 6HT-2L, Boxed Instrument | B59: 6735126101 | C59: 41199 | E59: Deinstalled | F59: MEDIAGNOST GMBH
A60: Guava easyCyte 8HT, Boxed Instrument | B60: 6735128085 | C60: 40935 | E60: Deinstalled | F60: University of Houston
A61: Guava easyCyte 8HT, Boxed Instrument | B61: 6735128146 | C61: 41206 | E61: Deinstalled | F61: University of Virginia
A62: Guava easyCyte 8HT, Boxed Instrument | B62: 6735128160 | C62: 41473 | E62: Deinstalled | F62: XIANGYA HOSPITAL CENTRAL SOUTH UNIVERSITY
A63: Guava easyCyte 8HT, Boxed Instrument | B63: 6735128167 | C63: 41309 | E63: Deinstalled | F63: University of Texas at Austin
B64: 673512S013 | C64: 41000 | E64: Installed | F64: University of California, Berkeley
...

Sheet Pricing Data
A1: Display Name | B1: Last Purchase Price | C1: Sale Unit | D1: Unit Price | E1: Price Level | F1: Currency | G1: Part Number | H1: Item Internal ID
A2: Value contract deductible | D2: 750 | F2: US Dollar | G2: Value
A3: On-Site Support (2 days) | D3: 7571 | F3: US Dollar | G3: 60020
A4: Basic contract deductible | F4: US Dollar
A5: Vacuum Manifold | B5: 58.56 | C5: Each | D5: 274.64 | E5: List Price | F5: US Dollar | G5: N0-00001 | H5: 34749
A6: Mounting Plate | B6: 2.12 | C6: Each | D6: 7.76 | E6: List Price | F6: US Dollar | G6: N0-00002 | H6: 16742
A7: Valve Guide | B7: 7.46 | C7: Each | D7: 22.38 | E7: List Price | F7: US Dollar | G7: N0-00003 | H7: 16743
A8: Pinch Hammer | B8: 0 | C8: Each | D8: 33.57 | E8: List Price | F8: US Dollar | G8: N0-00004 | H8: 16744
A9: Pinch Head | B9: 0 | C9: Each | D9: 80.61 | E9: List Price | F9: US Dollar | G9: N0-00005 | H9: 16745
A10: DeGasser Bracket | B10: 3.34 | C10: Each | D10: 12.53 | E10: List Price | F10: US Dollar | G10: N0-00006 | H10: 16746
A11: Lens Retaining Cover | B11: 3.6 | C11: Each | D11: 37.38 | E11: List Price | F11: US Dollar | G11: N0-00009 | H11: 16747
A12: Lens Barrel | B12: 21.81 | C12: Each | D12: 141.56 | E12: List Price | F12: US Dollar | G12: N0-00010 | H12: 16748
A13: Flow Cell Body | B13: 114.06 | C13: Each | D13: 268.71 | E13: List Price | F13: US Dollar | G13: N0-00011 | H13: 16752
A14: Flow Cell Exit | B14: 20.57 | C14: Each | D14: 53.73 | E14: List Price | F14: US Dollar | G14: N0-00012 | H14: 16753
A15: SIT Base | B15: 12.69 | C15: Each | D15: 38.07 | E15: List Price | F15: US Dollar | G15: N0-00013 | H15: 16754
A16: Red Prism Block | B16: 11.49 | C16: Each | D16: 57.09 | E16: List Price | F16: US Dollar | G16: N0-00014 | H16: 16757
... A1085: 0.07" EPDM O-ring Cord Stock | B1085: 0.27 | C1085: Foot | D1085: 0.02461 | E1085: List Price | F1085: US Dollar | G1085: N4-00095 | H1085: 75631
A1087: MMC 9616K11
A1088: O-RING, AS568A-159, EPDM 70 DURO | B1088: 12.16 | C1088: Each | D1088: 0.48 | E1088: List Price | F1088: US Dollar | G1088: N4-00100 | H1088: 15287
A1089: 1/4-28 x 1/8 FEMALE Luer BARB PANEL MT | B1089: 0.57 | C1089: Each | D1089: 1.52 | E1089: List Price | F1089: US Dollar | G1089: N4-00104 | H1089: 15319
A1090: Tee Tube Fitting with Classic Series Barbs, 1/8" (3.2 | B1090: 1.04 | C1090: Each | D1090: 2.67 | E1090: List Price | F1090: US Dollar | G1090: N4-00105 | H1090: 15339
A1091: Aria 1/32" Ferrule for PEEK Tubing in PMI Kit | B1091: 2 | C1091: Each | D1091: 9.21 | E1091: List Price | F1091: US Dollar | G1091: N4-00106 | H1091: 15342
A1092: ALMOND BULKHEAD 1/8" | B1092: 7.91 | C1092: Each | D1092: 41.91 | E1092: List Price | F1092: US Dollar | G1092: N4-00107 | H1092: 15370
A1093: FEMALE 1/4 NPT COLDER | B1093: 6.47 | C1093: Each | D1093: 29.43 | E1093: List Price | F1093: US Dollar | G1093: N4-00112 | H1093: 15373
A1094: ALMOND MALE COLDER 1/8" | B1094: 5.51 | C1094: Each | D1094: 18.33 | E1094: List Price | F1094: US Dollar | G1094: N4-00114 | H1094: 15376
A1095: ORG MALE COLDER 1/8" | B1095: 7.05 | C1095: Each | D1095: 18.33 | E1095: List Price | F1095: US Dollar | G1095: N4-00116 | H1095: 49212
A1096: SHEATH LEVEL SENSOR CAP | B1096: 3.56 | C1096: Each | D1096: 46.68 | E1096: List Price | F1096: US Dollar | G1096: N4-00118 | H1096: 15485
A1097: NC FLOAT SWITCH Brown Wires | B1097: 35.74 | C1097: Each | D1097: 94.74 | E1097: List Price | F1097: US Dollar | G1097: N4-00120 | H1097: 15490
A1098: Pressure Transducer Athena/Rainbow | B1098: 48.99 | C1098: Each | D1098: 183 | E1098: List Price | F1098: US Dollar | G1098: N4-00122 | H1098: 15567
A1099: 4L Tank | B1099: 126.9 | C1099: Each | D1099: 137.22 | E1099: List Price | F1099: US Dollar | G1099: N4-00124 | H1099: 15568
... A2662: RYV Upgrade (Monthly) | B2662: 0 | C2662: Each | D2662: 525 | E2662: List Price | F2662: US Dollar | G2662: N9-90097 | H2662: 105652
A2663: OQ Package (2PM visits) | B2663: 0 | D2663: 10500 | E2663: List Price | F2663: US Dollar | G2663: N9-90099 | H2663: 68075
A2664: OQ Package (All service visits) | B2664: 0 | D2664: 15750 | E2664: List Price | F2664: US Dollar | G2664: N9-90100 | H2664: 68076
A2665: IQ/OQ | B2665: 0 | D2665: 10500 | E2665: List Price | F2665: US Dollar | G2665: N9-90101 | H2665: 22353
A2666: Annual Surcharge | B2666: 0 | C2666: Each | D2666: 1313 | E2666: List Price | F2666: US Dollar | G2666: N9-90102 | H2666: 65838
A2667: Quarterly Surcharge | B2667: 0 | C2667: Each | D2667: 2625 | E2667: List Price | F2667: US Dollar | G2667: N9-90103 | H2667: 65839
A2668: BSL3/4 Surcharge | B2668: 0 | C2668: Each | D2668: 10500 | E2668: List Price | F2668: US Dollar | G2668: N9-90104 | H2668: 109579
A2669: BSL3/4 Surcharge | B2669: 0 | C2669: Each | D2669: 10000 | E2669: List Price | F2669: US Dollar | G2669: N9-90104-INA | H2669: 65840
A2670: Priority Response | B2670: 0 | C2670: Each | D2670: 1575 | E2670: List Price | F2670: US Dollar | G2670: N9-90105 | H2670: 20180
A2671: Cytek Spectral Cytometry Additional Training Provisions | B2671: 0 | C2671: Each | D2671: 5516 | E2671: List Price | F2671: US Dollar | G2671: N9-90106 | H2671: 68301
...

Sheet Cytek Service Quoting Old
C2: ='FSE Input Old'!A3 -> Brad Ballard | F2: ="QUOTE#: "&'FSE Input Old'!$D$3&" "&'FSE Input Old'!$B$3 -> #REF!
C3: ='FSE Input Old'!C3 -> #REF!
C4: ='FSE Input Old'!E3 -> #REF!
C7: Item | D7: Description | E7: Product Number | F7: Qty | G7: List Price | H7: Net Price | I7: Ext. Price
C8: =IF(D8="", "", "1") -> 1 | D8: =IF('FSE Input Old'!A7<>"", 'FSE Input Old'!A7, IF('FSE Input Old'!E7<>"", 'FSE Input Old'!E7, "")) -> On-Site Support (2 days) | E8: =IF('FSE Input Old'!B7<>"", 'FSE Input Old'!B7, IF('FSE Input Old'!F7<>"", 'FSE Input Old'!F7, "")) -> 60020 | F8: =IF(ISBLANK('FSE Input Old'!D7),"",'FSE Input Old'!D7) -> 1 | G8: =IF('FSE Input Old'!C7<>"", 'FSE Input Old'!C7, IF('FSE Input Old'!G7<>"", 'FSE Input Old'!G7, "")) -> 7571 | H8: =IF(G8="", "", IF(ISNUMBER(SEARCH("on-site", D8)), G8, IF(ISNUMBER(SEARCH("basic", 'FSE Input Old'!F$3)), G8*0.9, IF(ISNUMBER(SEARCH("value", 'FSE Input Old'!F$3)), G8-750, "") ) ) ) -> 7571 | I8: =IF(G8="","",H8*F8) -> 7571
C9: =IF(D9="", "", "2") -> 2 | D9: =IF('FSE Input Old'!A8<>"", 'FSE Input Old'!A8, IF('FSE Input Old'!E8<>"", 'FSE Input Old'!E8, "")) -> guava eacyCyte HT Preventative Maintenance | E9: =IF('FSE Input Old'!B8<>"", 'FSE Input Old'!B8, IF('FSE Input Old'!F8<>"", 'FSE Input Old'!F8, "")) -> PM-EASYCYTE-HT | F9: =IF(ISBLANK('FSE Input Old'!D8),"",'FSE Input Old'!D8) -> 1 | G9: =IF('FSE Input Old'!C8<>"", 'FSE Input Old'!C8, IF('FSE Input Old'!G8<>"", 'FSE Input Old'!G8, "")) -> 4814 | H9: =IF(G9="", "", IF(ISNUMBER(SEARCH("on-site", D9)), G9, IF(ISNUMBER(SEARCH("basic", 'FSE Input Old'!F$3)), G9*0.9, IF(ISNUMBER(SEARCH("value", 'FSE Input Old'!F$3)), G9-750, "") ) ) ) | I9: =IF(G9="","",H9*F9) -> #VALUE!
C10: =IF(D10="", "", "3") -> 3 | D10: =IF('FSE Input Old'!A9<>"", 'FSE Input Old'!A9, IF('FSE Input Old'!E9<>"", 'FSE Input Old'!E9, "")) -> Sheath Filter, Rainbow | E10: =IF('FSE Input Old'!B9<>"", 'FSE Input Old'!B9, IF('FSE Input Old'!F9<>"", 'FSE Input Old'!F9, "")) -> N4-00025 | F10: =IF(ISBLANK('FSE Input Old'!D9),"",'FSE Input Old'!D9) -> 1 | G10: =IF('FSE Input Old'!C9<>"", 'FSE Input Old'!C9, IF('FSE Input Old'!G9<>"", 'FSE Input Old'!G9, "")) -> 192.45 | H10: =IF(G10="", "", IF(ISNUMBER(SEARCH("on-site", D10)), G10, IF(ISNUMBER(SEARCH("basic", 'FSE Input Old'!F$3)), G10*0.9, IF(ISNUMBER(SEARCH("value", 'FSE Input Old'!F$3)), G10-750, "") ) ) ) | I10: =IF(G10="","",H10*F10) -> #VALUE!
C11: =IF(D11="", "", "4") | D11: =IF('FSE Input Old'!A10<>"", 'FSE Input Old'!A10, IF('FSE Input Old'!E10<>"", 'FSE Input Old'!E10, "")) | E11: =IF('FSE Input Old'!B10<>"", 'FSE Input Old'!B10, IF('FSE Input Old'!F10<>"", 'FSE Input Old'!F10, "")) | F11: =IF(ISBLANK('FSE Input Old'!D10),"",'FSE Input Old'!D10) | G11: =IF('FSE Input Old'!C10<>"", 'FSE Input Old'!C10, IF('FSE Input Old'!G10<>"", 'FSE Input Old'!G10, "")) | H11: =IF(G11="", "", IF(ISNUMBER(SEARCH("on-site", D11)), G11, IF(ISNUMBER(SEARCH("basic", 'FSE Input Old'!F$3)), G11*0.9, IF(ISNUMBER(SEARCH("value", 'FSE Input Old'!F$3)), G11-750, "") ) ) ) | I11: =IF(G11="","",H11*F11)
C13: Shipping & Handling Estimate
C14: Total | I14: =SUM(I15,I8:I11) -> #VALUE!
G49: ="QUOTE#: "&'FSE Input Old'!$D$3&" "&'FSE Input Old'!$B$3 -> #REF!
G101: ="QUOTE#: "&'FSE Input Old'!$D$3&" "&'FSE Input Old'!$B$3 -> #REF!
G153: ="QUOTE#: "&'FSE Input Old'!$D$3&" "&'FSE Input Old'!$B$3 -> #REF!

Sheet FSE Input Old
A1: CUSTOMER INFORMATION
A2: Name of customer requesting service/part: | B2: Instrument SN: | C2: Facility name: | D2: Shortened Facility name (ex. BCH): | E2: Facility Address: | F2: Contract type:
A3: Brad Ballard | B3: U0286 | C3: =VLOOKUP(B3,#REF!,2,FALSE) -> #REF! | D3: =VLOOKUP(C3,#REF!,2,FALSE) -> #REF! | E3: =VLOOKUP(B3,#REF!,19,FALSE) -> #REF! | F3: =VLOOKUP(B3,#REF!,9,FALSE) -> #REF!
A5: SERVICE TYPE / PART NAME
A6: Service Type/ Part Name | B6: Service Type/Part Number | C6: Service Type/ Part Price | D6: Quantity | E6: Service Type / Part Name (if not listed) | F6: Service Type Part Number (if not listed) | G6: Price of Service Type / Part (if not listed)
A7: On-Site Support (2 days) | B7: =IF(A7="","",VLOOKUP(A7,'Pricing Data'!A$2:H5436,7,FALSE)) -> 60020 | C7: =IF(A7="","",VLOOKUP(A7,'Pricing Data'!A2:H5436,4,FALSE)) -> 7571 | D7: 1
A8: guava eacyCyte HT Preventative Maintenance | B8: =IF(A8="","",VLOOKUP(A8,'Pricing Data'!A$2:H5437,7,FALSE)) -> PM-EASYCYTE-HT | C8: =IF(A8="","",VLOOKUP(A8,'Pricing Data'!A2:H5437,4,FALSE)) -> 4814 | D8: 1
A9: Sheath Filter, Rainbow | B9: =IF(A9="","",VLOOKUP(A9,'Pricing Data'!A$2:H5438,7,FALSE)) -> N4-00025 | C9: =IF(A9="","",VLOOKUP(A9,'Pricing Data'!A2:H5438,4,FALSE)) -> 192.45 | D9: 1
B10: =IF(A10="","",VLOOKUP(A10,'Pricing Data'!A2:H5439,7,FALSE)) | C10: =IF(A10="","",VLOOKUP(A10,'Pricing Data'!A2:H5439,4,FALSE))
B18: Name of customer requesting service/part: | C18: Brad Ballard | E18: SERVICE TYPE / PART NAME | F18: Service Type/ Part Name | G18: On-Site Support (2 days) | H18: guava eacyCyte HT Preventative Maintenance | I18: Sheath Filter, Rainbow
B19: Instrument SN: | C19: U0286 | F19: Service Type/Part Number | G19: =IF(G18="","",VLOOKUP(G18,'Pricing Data'!$B18:HAB25,7,FALSE)) -> #N/A | H19: =IF(H18="","",VLOOKUP(H18,'Pricing Data'!$B18:HAC25,7,FALSE)) -> #N/A | I19: =IF(I18="","",VLOOKUP(I18,'Pricing Data'!$B18:HAD25,7,FALSE)) -> #N/A | J19: =IF(J18="","",VLOOKUP(J18,'Pricing Data'!B18:HAE25,7,FALSE))
B20: Facility name: | C20: =VLOOKUP(C19,#REF!,2,FALSE) -> #REF! | F20: Service Type/ Part Price | G20: =IF(G18="","",VLOOKUP(G18,'Pricing Data'!B18:HAB25,4,FALSE)) -> #N/A | H20: =IF(H18="","",VLOOKUP(H18,'Pricing Data'!B18:HAC25,4,FALSE)) -> #N/A | I20: =IF(I18="","",VLOOKUP(I18,'Pricing Data'!B18:HAD25,4,FALSE)) -> #N/A | J20: =IF(J18="","",VLOOKUP(J18,'Pricing Data'!B18:HAE25,4,FALSE))
B21: Shortened Facility name (ex. BCH): | C21: =VLOOKUP(C20,#REF!,2,FALSE) -> #REF! | F21: Quantity | G21: 1 | H21: 1 | I21: 1
B22: Facility Address: | C22: =VLOOKUP(C19,#REF!,19,FALSE) -> #REF! | F22: Service Type / Part Name (if not listed)
B23: Contract type: | C23: =VLOOKUP(C19,#REF!,9,FALSE) -> #REF! | F23: Service Type Part Number (if not listed)
F24: Price of Service Type / Part (if not listed)
A32: SERVICE TYPE/PART NAME - SERVICE QUOTE
B33: Part 1 | C33: Part 2 | D33: Part 3 | E33: Part 4
A34: Service Type/ Part Name | B34: On-Site Support (2 days) | C34: guava eacyCyte HT Preventative Maintenance | D34: Sheath Filter, Rainbow
A35: Service Type/Part Number | B35: =IF(B34="","",VLOOKUP(B34,'Pricing Data'!$B31:GZX38,7,FALSE)) -> #N/A | C35: =IF(C34="","",VLOOKUP(C34,'Pricing Data'!$B31:GZY38,7,FALSE)) -> #N/A | D35: =IF(D34="","",VLOOKUP(D34,'Pricing Data'!$B31:GZZ38,7,FALSE)) -> #N/A | E35: =IF(E34="","",VLOOKUP(E34,'Pricing Data'!#REF!,7,FALSE))
A36: Service Type/ Part Price | B36: =IF(B34="","",VLOOKUP(B34,'Pricing Data'!#REF!,4,FALSE)) -> #REF! | C36: =IF(C34="","",VLOOKUP(C34,'Pricing Data'!#REF!,4,FALSE)) -> #REF! | D36: =IF(D34="","",VLOOKUP(D34,'Pricing Data'!#REF!,4,FALSE)) -> #REF! | E36: =IF(E34="","",VLOOKUP(E34,'Pricing Data'!#REF!,4,FALSE))
A37: Quantity | B37: 1 | C37: 1 | D37: 1
A38: Service Type / Part Name (if not listed)
A39: Service Type Part Number (if not listed)
A40: Price of Service Type / Part (if not listed)
