Workbook

Sheet Admin
A2: Relocation fee???
H7: basic/PMI Bronze has 10% discount
A8: Service and Parts | B8: TS email, contract matters for discount
A9: Move | B9: contract doesn't matter
A10: Parts ONLY | B10: orders email, contract matters for discount
H11: protection on cells - turn into API
C15: Contract pricing - service
C16: Contract | D16: ='FSE Input'!B13 -> 0 | E16: labor? | F16: cost | G16: premium contract | H16: 20% discount | I16: 10% dicsount | J16: final price
C17: part 1 | D17: =IF('FSE Input'!B17<>"",'FSE Input'!B17,IF('FSE Input'!B21<>"",'FSE Input'!B21,"")) -> On-Site Support (2 days) | E17: =IF(OR(ISNUMBER(SEARCH("site",D17)),ISNUMBER(SEARCH("service",D17)),ISNUMBER(SEARCH("support",D17))),"Yes","No") -> Yes | F17: =IF('FSE Input'!B19<>"",'FSE Input'!B19,IF('FSE Input'!B23<>"",'FSE Input'!B23,"")) -> 7571 | G17: =IF(E17="Yes", F17, IF(OR($D$16="Premium", $D$16="Gold", ISNUMBER(SEARCH("COMPLET",$D$16))), F17, "")) -> 7571 | H17: =IF(E17="Yes", F17, IF(OR($D$16="VALUE", $D$16="Silver", ISNUMBER(SEARCH("INTERMED",$D$16))), F17*0.8, "")) -> 7571 | I17: =IF(E17="Yes", F17, IF(OR($D$16="PMI", $D$16="Bronze", ISNUMBER(SEARCH("BASIC",$D$16))), F17*0.9, "")) -> 7571 | J17: =IF(E17="Yes", F17, IF(OR($D$16="Premium", $D$16="Gold", ISNUMBER(SEARCH("COMPLET",$D$16))), F17, IF(OR($D$16="VALUE", $D$16="Silver", ISNUMBER(SEARCH("INTERMED",$D$16))), F17*0.8, IF(OR($D$16="PMI", $D$16="Bronze", ISNUMBER(SEARCH("BASIC",$D$16))), F17*0.9, "" ) ) ) ) -> 7571
C18: part 2 | D18: =IF('FSE Input'!B25<>"",'FSE Input'!B25,IF('FSE Input'!B29<>"",'FSE Input'!B29,"")) | E18: =IF(OR(ISNUMBER(SEARCH("site",D18)),ISNUMBER(SEARCH("service",D18)),ISNUMBER(SEARCH("support",D18))),"Yes","No") -> No | F18: =IF('FSE Input'!B27<>"",'FSE Input'!B27,IF('FSE Input'!B31<>"",'FSE Input'!B31,"")) | G18: =IF(E18="Yes", F18, IF(OR($D$16="Premium", $D$16="Gold", ISNUMBER(SEARCH("COMPLET",$D$16))), F18, "")) | H18: =IF(E18="Yes", F18, IF(OR($D$16="VALUE", $D$16="Silver", ISNUMBER(SEARCH("INTERMED",$D$16))), F18*0.8, "")) | I18: =IF(E18="Yes", F18, IF(OR($D$16="PMI", $D$16="Bronze", ISNUMBER(SEARCH("BASIC",$D$16))), F18*0.9, "")) | J18: =IF(E18="Yes", F18, IF(OR($D$16="Premium", $D$16="Gold", ISNUMBER(SEARCH("COMPLET",$D$16))), F18, IF(OR($D$16="VALUE", $D$16="Silver", ISNUMBER(SEARCH("INTERMED",$D$16))), F18*0.8, IF(OR($D$16="PMI", $D$16="Bronze", ISNUMBER(SEARCH("BASIC",$D$16))), F18*0.9, "" ) ) ) )
C19: part 3 | D19: =IF('FSE Input'!B33<>"",'FSE Input'!B33,IF('FSE Input'!B37<>"",'FSE Input'!B37,"")) | E19: =IF(OR(ISNUMBER(SEARCH("site",D19)),ISNUMBER(SEARCH("service",D19)),ISNUMBER(SEARCH("support",D19))),"Yes","No") -> No | F19: =IF('FSE Input'!B35<>"",'FSE Input'!B35,IF('FSE Input'!B39<>"",'FSE Input'!B39,"")) | G19: =IF(E19="Yes", F19, IF(OR($D$16="Premium", $D$16="Gold", ISNUMBER(SEARCH("COMPLET",$D$16))), F19, "")) | H19: =IF(E19="Yes", "", IF(OR($D$16="VALUE", $D$16="Silver", ISNUMBER(SEARCH("INTERMED",$D$16))), F19*0.8, "")) | I19: =IF(E19="Yes", F19, IF(OR($D$16="PMI", $D$16="Bronze", ISNUMBER(SEARCH("BASIC",$D$16))), F19*0.9, "")) | J19: =IF(E19="Yes", F19, IF(OR($D$16="Premium", $D$16="Gold", ISNUMBER(SEARCH("COMPLET",$D$16))), F19, IF(OR($D$16="VALUE", $D$16="Silver", ISNUMBER(SEARCH("INTERMED",$D$16))), F19*0.8, IF(OR($D$16="PMI", $D$16="Bronze", ISNUMBER(SEARCH("BASIC",$D$16))), F19*0.9, "" ) ) ) )
C20: part 4 | D20: =IF('FSE Input'!B41<>"",'FSE Input'!B41,IF('FSE Input'!B45<>"",'FSE Input'!B45,"")) | E20: =IF(OR(ISNUMBER(SEARCH("site",D20)),ISNUMBER(SEARCH("service",D20)),ISNUMBER(SEARCH("support",D20))),"Yes","No") -> No | F20: =IF('FSE Input'!B43<>"",'FSE Input'!B43,IF('FSE Input'!B47<>"",'FSE Input'!B47,"")) | G20: =IF(E20="Yes", F20, IF(OR($D$16="Premium", $D$16="Gold", ISNUMBER(SEARCH("COMPLET",$D$16))), F20, "")) | H20: =IF(E20="Yes", F20, IF(OR($D$16="VALUE", $D$16="Silver", ISNUMBER(SEARCH("INTERMED",$D$16))), F20*0.8, "")) | I20: =IF(E20="Yes", F20, IF(OR($D$16="PMI", $D$16="Bronze", ISNUMBER(SEARCH("BASIC",$D$16))), F20*0.9, "")) | J20: =IF(E20="Yes", F20, IF(OR($D$16="Premium", $D$16="Gold", ISNUMBER(SEARCH("COMPLET",$D$16))), F20, IF(OR($D$16="VALUE", $D$16="Silver", ISNUMBER(SEARCH("INTERMED",$D$16))), F20*0.8, IF(OR($D$16="PMI", $D$16="Bronze", ISNUMBER(SEARCH("BASIC",$D$16))), F20*0.9, "" ) ) ) )
C22: contract pricing - parts
C23: contract | D23: ='FSE Input'!E13 -> Premium | E23: labor? | F23: cost | G23: premium | H23: 20% discount | I23: 10% discount | J23: final price
C24: part 1 | D24: =IF('FSE Input'!E17<>"",'FSE Input'!E17,IF('FSE Input'!E21<>"",'FSE Input'!E21,"")) -> On-Site Support (2 days) | E24: =IF(OR(ISNUMBER(SEARCH("site",D24)),ISNUMBER(SEARCH("service",D24)),ISNUMBER(SEARCH("support",D24))),"Yes","No") -> Yes | F24: =IF('FSE Input'!E19<>"",'FSE Input'!E19,IF('FSE Input'!E23<>"",'FSE Input'!E23,"")) -> 7571 | G24: =IF(E24="Yes", F24, IF(OR($D$23="Premium", $D$23="Gold", ISNUMBER(SEARCH("COMPLET",$D$23))), F24, "")) -> 7571 | H24: =IF(E24="Yes", F24, IF(OR($D$23="VALUE", $D$23="Silver", ISNUMBER(SEARCH("INTERMED",$D$23))), F24*0.8, "")) -> 7571 | I24: =IF(E24="Yes", F24, IF(OR($D$23="PMI", $D$23="Bronze", ISNUMBER(SEARCH("BASIC",$D$23))), F24*0.9, "")) -> 7571 | J24: =IF(E24="Yes", F24, IF(OR($D$23="Premium", $D$23="Gold", ISNUMBER(SEARCH("COMPLET",$D$23))), F24, IF(OR($D$23="VALUE", $D$23="Silver", ISNUMBER(SEARCH("INTERMED",$D$23))), F24*0.8, IF(OR($D$23="PMI", $D$23="Bronze", ISNUMBER(SEARCH("BASIC",$D$23))), F24*0.9, "" ) ) ) ) -> 7571
C25: part 2 | D25: =IF('FSE Input'!E25<>"",'FSE Input'!E25,IF('FSE Input'!E29<>"",'FSE Input'!E29,"")) -> Flow Cell Body | E25: =IF(OR(ISNUMBER(SEARCH("site",D25)),ISNUMBER(SEARCH("service",D25)),ISNUMBER(SEARCH("support",D25))),"Yes","No") -> No | F25: =IF('FSE Input'!E27<>"",'FSE Input'!E27,IF('FSE Input'!E31<>"",'FSE Input'!E31,"")) -> 268.71 | G25: =IF(E25="Yes", F25, IF(OR($D$23="Premium", $D$16="Gold", ISNUMBER(SEARCH("COMPLET",$D$23))), F25, "")) -> 268.71 | H25: =IF(E25="Yes", F25, IF(OR($D$23="VALUE", $D$23="Silver", ISNUMBER(SEARCH("INTERMED",$D$23))), F25*0.8, "")) | I25: =IF(E25="Yes", F25, IF(OR($D$16="PMI", $D$16="Bronze", ISNUMBER(SEARCH("BASIC",$D$16))), F25*0.9, "")) | J25: =IF(E25="Yes", F25, IF(OR($D$23="Premium", $D$23="Gold", ISNUMBER(SEARCH("COMPLET",$D$23))), F25, IF(OR($D$23="VALUE", $D$23="Silver", ISNUMBER(SEARCH("INTERMED",$D$23))), F25*0.8, IF(OR($D$23="PMI", $D$23="Bronze", ISNUMBER(SEARCH("BASIC",$D$23))), F25*0.9, "" ) ) ) ) -> 268.71
C26: part 3 | D26: =IF('FSE Input'!E33<>"",'FSE Input'!E33,IF('FSE Input'!E37<>"",'FSE Input'!E37,"")) -> Mounting Plate | E26: =IF(OR(ISNUMBER(SEARCH("site",D26)),ISNUMBER(SEARCH("service",D26)),ISNUMBER(SEARCH("support",D26))),"Yes","No") -> No | F26: =IF('FSE Input'!E35<>"",'FSE Input'!E35,IF('FSE Input'!E39<>"",'FSE Input'!E39,"")) -> 7.76 | G26: =IF(E26="Yes", F26, IF(OR($D$23="Premium", $D$23="Gold", ISNUMBER(SEARCH("COMPLET",$D$23))), F26, "")) -> 7.76 | H26: =IF(E26="Yes", "", IF(OR($D$23="VALUE", $D$23="Silver", ISNUMBER(SEARCH("INTERMED",$D$23))), F26*0.8, "")) | I26: =IF(E26="Yes", F26, IF(OR($D$16="PMI", $D$16="Bronze", ISNUMBER(SEARCH("BASIC",$D$16))), F26*0.9, "")) | J26: =IF(E26="Yes", F26, IF(OR($D$23="Premium", $D$23="Gold", ISNUMBER(SEARCH("COMPLET",$D$23))), F26, IF(OR($D$23="VALUE", $D23="Silver", ISNUMBER(SEARCH("INTERMED",$D$23))), F26*0.8, IF(OR($D$23="PMI", $D$23="Bronze", ISNUMBER(SEARCH("BASIC",$D$23))), F26*0.9, "" ) ) ) ) -> 7.76
C27: part 4 | D27: =IF('FSE Input'!E41<>"",'FSE Input'!E41,IF('FSE Input'!E45<>"",'FSE Input'!E45,"")) -> generator | E27: =IF(OR(ISNUMBER(SEARCH("site",D27)),ISNUMBER(SEARCH("service",D27)),ISNUMBER(SEARCH("support",D27))),"Yes","No") -> No | F27: =IF('FSE Input'!E43<>"",'FSE Input'!E43,IF('FSE Input'!E47<>"",'FSE Input'!E47,"")) -> 800 | G27: =IF(E27="Yes", F27, IF(OR($D$23="Premium", $D$23="Gold", ISNUMBER(SEARCH("COMPLET",$D$23))), F27, "")) -> 800 | H27: =IF(E27="Yes", F27, IF(OR($D$23="VALUE", $D$23="Silver", ISNUMBER(SEARCH("INTERMED",$D$23))), F27*0.8, "")) | I27: =IF(E27="Yes", F27, IF(OR($D$16="PMI", $D$16="Bronze", ISNUMBER(SEARCH("BASIC",$D$16))), F27*0.9, "")) | J27: =IF(E27="Yes", F27, IF(OR($D$23="Premium", $D$23="Gold", ISNUMBER(SEARCH("COMPLET",$D$23))), F27, IF(OR($D$23="VALUE", $D$23="Silver", ISNUMBER(SEARCH("INTERMED",$D$23))), F27*0.8, IF(OR($D$23="PMI", $D$23="Bronze", ISNUMBER(SEARCH("BASIC",$D$23))), F27*0.9, "" ) ) ) ) -> 800
D34: need to include the if not listed here | F34: test if all work for if not listed
D35: note
D36: add a little popup that says if the contract is value, amke sure this is not the customer's first repair if so no quote needed
D37: how to do pricing? which cell has numbers? or combine everything into one

Sheet FSE Input
A1: What are you quoting?
A2: Service and Parts
A6: Use "Cytek Service Quoting" Tab to print quote | D6: Use "Cytek Parts Quoting" Tab to print quote
A7: CUSTOMER INFORMATION - SERVICE QUOTE | D7: Customer information - Parts Quote
A8: Name of customer requesting service/part: | B8: Alyssa Sanfillipo | D8: Name of customer requesting service/part: | E8: Mike Waring
A9: Instrument SN: | B9: R0732 | D9: Instrument SN: | E9: U1399
A10: Facility name: | B10: =VLOOKUP(B9,'Asset Data'!C$2:U$3586,2,FALSE) -> abata THERAPEUTICS | D10: Facility name: | E10: =VLOOKUP(E9,'Asset Data'!C$2:U$3586,2,FALSE) -> Ragon Institute of MGH MIT and Harvard
A11: Shortened Facility name | B11: =VLOOKUP(B10,'Asset Data'!D1:E3586,2,FALSE) -> ABATA | D11: Shortened Facility name | E11: =VLOOKUP(E10,'Asset Data'!D1:E3586,2,FALSE) -> RGON
A12: Facility Address: | B12: =VLOOKUP(B9,'Asset Data'!C2:U3586,19,FALSE) -> 100 Forge Street (2nd Floor), Watertown, Massachusetts 02472, U.S. | D12: Facility Address: | E12: =VLOOKUP(E9,'Asset Data'!C2:U3586,19,FALSE) -> Ragon Institute of MGH MIT and Harvard - 600 Main St, Cambridge, Massachusetts 02139, U.S.
A13: Contract type: | B13: =VLOOKUP(B9,'Asset Data'!C2:U3586,9,FALSE) -> 0 | D13: Contract type: | E13: =VLOOKUP(E9,'Asset Data'!C2:U3586,9,FALSE) -> Premium
A15: SERVICE TYPE/PART NAME - SERVICE QUOTE | D15: SERVICE TYPE/PART NAME - PARTS QUOTE
A16: PART 1 | D16: PART 1
A17: Service Type/ Part Name | B17: On-Site Support (2 days) | D17: Service Type/ Part Name | E17: On-Site Support (2 days)
A18: Service Type/Part Number | B18: =IF(B17="","",VLOOKUP(B17,'Pricing Data'!A$2:H5436,7,FALSE)) -> 60020 | D18: Service Type/Part Number | E18: =IF(E17="","",VLOOKUP(E17,'Pricing Data'!A$2:H5436,7,FALSE)) -> 60020
A19: Service Type/ Part Price | B19: =IF(B17="","",VLOOKUP(B17,'Pricing Data'!A$2:H5436,4,FALSE)) -> 7571 | D19: Service Type/ Part Price | E19: =IF(E17="","",VLOOKUP(E17,'Pricing Data'!A$2:H5436,4,FALSE)) -> 7571
A20: Quantity | B20: 1 | D20: Quantity | E20: 1
A21: Service Type / Part Name (if not listed) | D21: Service Type / Part Name (if not listed)
A22: Service Type Part Number (if not listed) | D22: Service Type Part Number (if not listed)
A23: Price of Service Type / Part (if not listed) | D23: Price of Service Type / Part (if not listed)
A24: PART 2 | D24: PART 2
A25: Service Type/ Part Name | D25: Service Type/ Part Name | E25: Flow Cell Body
A26: Service Type/Part Number | B26: =IF(B25="","",VLOOKUP(B25,'Pricing Data'!A$2:H5436,7,FALSE)) | D26: Service Type/Part Number | E26: =IF(E25="","",VLOOKUP(E25,'Pricing Data'!A$2:H5444,7,FALSE)) -> N0-00011
A27: Service Type/ Part Price | B27: =IF(B25="","",VLOOKUP(B25,'Pricing Data'!A$2:H5436,4,FALSE)) | D27: Service Type/ Part Price | E27: =IF(E25="","",VLOOKUP(E25,'Pricing Data'!A$2:H5444,4,FALSE)) -> 268.71
A28: Quantity | D28: Quantity | E28: 1
A29: Service Type / Part Name (if not listed) | D29: Service Type / Part Name (if not listed)
A30: Service Type Part Number (if not listed) | D30: Service Type Part Number (if not listed)
A31: Price of Service Type / Part (if not listed) | D31: Price of Service Type / Part (if not listed)
A32: PART 3 | D32: PART 3
A33: Service Type/ Part Name | D33: Service Type/ Part Name | E33: Mounting Plate
A34: Service Type/Part Number | B34: =IF(B33="","",VLOOKUP(B33,'Pricing Data'!A$2:H5436,7,FALSE)) | D34: Service Type/Part Number | E34: =IF(E33="","",VLOOKUP(E33,'Pricing Data'!A$2:H5452,7,FALSE)) -> N0-00002
A35: Service Type/ Part Price | B35: =IF(B33="","",VLOOKUP(B33,'Pricing Data'!A$2:H5436,4,FALSE)) | D35: Service Type/ Part Price | E35: =IF(E33="","",VLOOKUP(E33,'Pricing Data'!A$2:H5452,4,FALSE)) -> 7.76
A36: Quantity | D36: Quantity | E36: 1
A37: Service Type / Part Name (if not listed) | D37: Service Type / Part Name (if not listed)
A38: Service Type Part Number (if not listed) | D38: Service Type Part Number (if not listed)
A39: Price of Service Type / Part (if not listed) | D39: Price of Service Type / Part (if not listed)
A40: PART 4 | D40: PART 4
A41: Service Type/ Part Name | D41: Service Type/ Part Name
A42: Service Type/Part Number | B42: =IF(B41="","",VLOOKUP(B41,'Pricing Data'!A$2:H5436,7,FALSE)) | D42: Service Type/Part Number | E42: =IF(E41="","",VLOOKUP(E41,'Pricing Data'!A$2:H5460,7,FALSE))
A43: Service Type/ Part Price | B43: =IF(B41="","",VLOOKUP(B41,'Pricing Data'!A$2:H5436,4,FALSE)) | D43: Service Type/ Part Price | E43: =IF(E41="","",VLOOKUP(E41,'Pricing Data'!A$2:H5460,4,FALSE))
A44: Quantity | D44: Quantity | E44: 1
...

Sheet Cytek Service Quoting
C2: ='FSE Input'!B8 -> Alyssa Sanfillipo | F2: ="QUOTE#: "&'FSE Input'!$B$11&" "&'FSE Input'!$B$9 -> QUOTE#: ABATA R0732
C3: ='FSE Input'!B10 -> abata THERAPEUTICS
C4: ='FSE Input'!B12 -> 100 Forge Street (2nd Floor), Watertown, Massachusetts 02472, U.S.
C7: Item | D7: Description | E7: Product Number | F7: Qty | G7: List Price | H7: Net Price | I7: Ext. Price
C8: =IF(D8="", "", "1") -> 1 | D8: =IF('FSE Input'!B17<>"", 'FSE Input'!B17, IF('FSE Input'!B21<>"", 'FSE Input'!B21, "")) -> On-Site Support (2 days) | E8: =IF('FSE Input'!B18<>"", 'FSE Input'!B18, IF('FSE Input'!B22<>"", 'FSE Input'!B22, "")) -> 60020 | F8: =IF(ISBLANK('FSE Input'!B20),"",'FSE Input'!B20) -> 1 | G8: =IF('FSE Input'!B19<>"", 'FSE Input'!B19, IF('FSE Input'!B23<>"", 'FSE Input'!B23, "")) -> 7571 | H8: =IF(Admin!D17<>"",Admin!J17,"") -> 7571 | I8: =IF(G8="","",H8*F8) -> 7571
C9: =IF(D9="", "", "2") | D9: =IF('FSE Input'!B25<>"", 'FSE Input'!B25, IF('FSE Input'!B29<>"", 'FSE Input'!B29, "")) | E9: =IF('FSE Input'!B26<>"", 'FSE Input'!B26, IF('FSE Input'!B30<>"", 'FSE Input'!B30, "")) | F9: =IF(ISBLANK('FSE Input'!B28),"",'FSE Input'!B28) | G9: =IF('FSE Input'!B27<>"", 'FSE Input'!B27, IF('FSE Input'!B31<>"", 'FSE Input'!B31, "")) | H9: =IF(Admin!D18<>"",Admin!J18,"") | I9: =IF(G9="","",H9*F9)
C10: =IF(D10="", "", "3") | D10: =IF('FSE Input'!B33<>"", 'FSE Input'!B33, IF('FSE Input'!B37<>"", 'FSE Input'!B37, "")) | E10: =IF('FSE Input'!B34<>"", 'FSE Input'!B34, IF('FSE Input'!B38<>"", 'FSE Input'!B38, "")) | F10: =IF(ISBLANK('FSE Input'!B36),"",'FSE Input'!B36) | G10: =IF('FSE Input'!B35<>"", 'FSE Input'!B35, IF('FSE Input'!B39<>"", 'FSE Input'!B39, "")) | H10: =IF(Admin!D19<>"",Admin!J19,"") | I10: =IF(G10="","",H10*F10)
C11: =IF(D11="", "", "4") | D11: =IF('FSE Input'!B41<>"", 'FSE Input'!B41, IF('FSE Input'!B45<>"", 'FSE Input'!B45, "")) | E11: =IF('FSE Input'!B42<>"", 'FSE Input'!B42, IF('FSE Input'!B46<>"", 'FSE Input'!B46, "")) | F11: =IF(ISBLANK('FSE Input'!B44),"",'FSE Input'!B44) | G11: =IF('FSE Input'!B43<>"", 'FSE Input'!B43, IF('FSE Input'!B47<>"", 'FSE Input'!B47, "")) | H11: =IF(Admin!D20<>"",Admin!J20,"") | I11: =IF(G11="","",H11*F11)
C13: Shipping & Handling Estimate
C14: Total | I14: =SUM(I15,I8:I11) -> 7571
D16: Pre-Inspection/Recertification
G101: ="QUOTE#: "&'FSE Input Old'!$D$3&" "&'FSE Input Old'!$B$3 -> QUOTE#: MSU U0286
G153: ="QUOTE#: "&'FSE Input Old'!$D$3&" "&'FSE Input Old'!$B$3 -> QUOTE#: MSU U0286

Sheet Cytek Parts Quoting
C2: ='FSE Input'!E8 -> Mike Waring | F2: ="QUOTE#: "&'FSE Input'!$E$11&" "&'FSE Input'!$E$9 -> QUOTE#: RGON U1399
C3: ='FSE Input'!E10 -> Ragon Institute of MGH MIT and Harvard
C4: ='FSE Input'!E12 -> Ragon Institute of MGH MIT and Harvard - 600 Main St, Cambridge, Massachusetts 02139, U.S.
C7: Item | D7: Description | E7: Product Number | F7: Qty | G7: List Price | H7: Net Price | I7: Ext. Price
C8: =IF(D8="", "", "1") -> 1 | D8: =IF('FSE Input'!E17<>"", 'FSE Input'!E17, IF('FSE Input'!E21<>"", 'FSE Input'!E21, "")) -> On-Site Support (2 days) | E8: =IF('FSE Input'!E18<>"", 'FSE Input'!E18, IF('FSE Input'!E22<>"", 'FSE Input'!E22, "")) -> 60020 | F8: =IF(ISBLANK('FSE Input'!E20),"",'FSE Input'!E20) -> 1 | G8: =IF('FSE Input'!E19<>"", 'FSE Input'!E19, IF('FSE Input'!E23<>"", 'FSE Input'!E23, "")) -> 7571 | H8: =IF(Admin!D24<>"",Admin!J24,"") -> 7571 | I8: =IF(G8="","",H8*F8) -> 7571
C9: =IF(D9="", "", "2") -> 2 | D9: =IF('FSE Input'!E25<>"", 'FSE Input'!E25, IF('FSE Input'!E29<>"", 'FSE Input'!E29, "")) -> Flow Cell Body | E9: =IF('FSE Input'!E26<>"", 'FSE Input'!E26, IF('FSE Input'!E30<>"", 'FSE Input'!E30, "")) -> N0-00011 | F9: =IF(ISBLANK('FSE Input'!E28),"",'FSE Input'!E28) -> 1 | G9: =IF('FSE Input'!E27<>"", 'FSE Input'!E27, IF('FSE Input'!E31<>"", 'FSE Input'!E31, "")) -> 268.71 | H9: =IF(Admin!D25<>"",Admin!J25,"") -> 268.71 | I9: =IF(G9="","",H9*F9) -> 268.71
C10: =IF(D10="", "", "3") -> 3 | D10: =IF('FSE Input'!E33<>"", 'FSE Input'!E33, IF('FSE Input'!E37<>"", 'FSE Input'!E37, "")) -> Mounting Plate | E10: =IF('FSE Input'!E34<>"", 'FSE Input'!E34, IF('FSE Input'!E38<>"", 'FSE Input'!E38, "")) -> N0-00002 | F10: =IF(ISBLANK('FSE Input'!E36),"",'FSE Input'!E36) -> 1 | G10: =IF('FSE Input'!E35<>"", 'FSE Input'!E35, IF('FSE Input'!E39<>"", 'FSE Input'!E39, "")) -> 7.76 | H10: =IF(Admin!D26<>"",Admin!J26,"") -> 7.76 | I10: =IF(G10="","",H10*F10) -> 7.76
C11: =IF(D11="", "", "4") -> 4 | D11: =IF('FSE Input'!E41<>"", 'FSE Input'!E41, IF('FSE Input'!E45<>"", 'FSE Input'!E45, "")) -> generator | E11: =IF('FSE Input'!E42<>"", 'FSE Input'!E42, IF('FSE Input'!E46<>"", 'FSE Input'!E46, "")) -> u1093 | F11: =IF(ISBLANK('FSE Input'!E44),"",'FSE Input'!E44) -> 1 | G11: =IF('FSE Input'!E43<>"", 'FSE Input'!E43, IF('FSE Input'!E47<>"", 'FSE Input'!E47, "")) -> 800 | H11: =IF(Admin!D27<>"",Admin!J27,"") -> 800 | I11: =IF(G11="","",H11*F11) -> 800
C13: Shipping & Handling Estimate
C14: Total | I14: =SUM(I15,I8:I11) -> 8647.47
G49: ="QUOTE#: "&'FSE Input Old'!$D$3&" "&'FSE Input Old'!$B$3 -> QUOTE#: MSU U0286
G101: ="QUOTE#: "&'FSE Input Old'!$D$3&" "&'FSE Input Old'!$B$3 -> QUOTE#: MSU U0286
G153: ="QUOTE#: "&'FSE Input Old'!$D$3&" "&'FSE Input Old'!$B$3 -> QUOTE#: MSU U0286

Sheet Asset Data
A1: Region | B1: Country | C1: Asset Name | D1: Account: Account Name | E1: shortened facility name | F1: Service Territory: Name | G1: Primary Service Technician | H1: Primary FAS | I1: Account Owner | J1: Synced Contract: Contract Number | K1: Synced Contract: Contract Type | L1: Synced Contract: Status | M1: Product: Product Name | N1: Contact: Full Name | O1: Contact: Email | P1: Special Handling Indicator | Q1: Street | R1: City | S1: State and Zip code | T1: Country | U1: Installed Address
A2: North America | B2: U.S. | C2: 8470060264 | D2: 10X GENOMICS | E2: 10XGEN | F2: US-Oakland | H2: Jonathan Paw | I2: Karen Young | J2: 00030294 | K2: SLA-EC-COMPLETE | L2: Activated | M2: Guava easyCyte 6HT-2L | N2: JAZY CHEUNG | O2: jazy.cheung@10xgenomics.com | Q2: 6230 STONERIDGE MALL RD | R2: PLEASANTON | S2: California 94588 | T2: U.S. | U2: =_xlfn.TEXTJOIN(", ", TRUE, Q2, R2, S2, T2) -> 6230 STONERIDGE MALL RD, PLEASANTON, California 94588, U.S.
A3: North America | B3: U.S. | C3: 8470060262 | D3: 10X GENOMICS | E3: 10XGEN | F3: US-Oakland | H3: Jonathan Paw | I3: Karen Young | J3: 00036340 | K3: SLA-EC-COMPLETE | L3: Activated | M3: Guava easyCyte 6HT-2L | N3: Taylor Wyatt | O3: taylor.wyatt@10xgenomics.com | Q3: 5500 Stoneridge Mall Rd | R3: PLEASANTON | S3: California 94588 | T3: U.S. | U3: =_xlfn.TEXTJOIN(", ", TRUE, Q3, R3, S3, T3) -> 5500 Stoneridge Mall Rd, PLEASANTON, California 94588, U.S.
A4: North America | B4: U.S. | C4: 8470060146 | D4: 10X GENOMICS | E4: 10XGEN | F4: US-Oakland | H4: Jonathan Paw | I4: Karen Young | J4: 00032541 | K4: SLA-EC-COMPLETE | L4: Expired | M4: Guava easyCyte 6HT-2L | N4: EMIL ANTHONY GIMENEZ | O4: emilanthony.gimenez@10xgenomics.com | Q4: 5500 Stoneridge Mall Rd | R4: PLEASANTON | S4: California 94588 | T4: U.S. | U4: =_xlfn.TEXTJOIN(", ", TRUE, Q4, R4, S4, T4) -> 5500 Stoneridge Mall Rd, PLEASANTON, California 94588, U.S.
A5: North America | B5: U.S. | C5: 6735148243 | D5: 1GLOBE HEALTH INSTITUTE | E5: GHI | F5: US-Boston | H5: Mark Stottlemyer | I5: Lindsay Albert | M5: Guava easyCyte 8HT | N5: AMANDA PIAZZA | O5: apiazza1@1globe-usa.com | Q5: 333 PROVIDENCE HWY | R5: NORWOOD | S5: Massachusetts 02062 | T5: U.S. | U5: =_xlfn.TEXTJOIN(", ", TRUE, Q5, R5, S5, T5) -> 333 PROVIDENCE HWY, NORWOOD, Massachusetts 02062, U.S.
A6: North America | B6: U.S. | C6: 8470050267 | D6: 23ANDME INC | E6: 23&M3 | F6: US-San Francisco | H6: Jonathan Paw | I6: Alexandra Dudschus | M6: Guava easyCyte 5HT, Boxed Instrument | Q6: 349 OYSTER POINT BLVD | R6: SOUTH SAN FRANCISCO | S6: California 94080 | T6: U.S. | U6: =_xlfn.TEXTJOIN(", ", TRUE, Q6, R6, S6, T6) -> 349 OYSTER POINT BLVD, SOUTH SAN FRANCISCO, California 94080, U.S.
A7: North America | B7: U.S. | C7: EC221246C1 | D7: 3M | E7: 3M | F7: US-Minneapolis | H7: Joel Crespo | I7: Gregory Kleedtke | M7: Guava easyCyte 6HT-2L | N7: EMILY JULIK | O7: ejulik@mmm.com | Q7: 3M CTR BLDG 201-2E-232 | R7: MAPLEWOOD | S7: Minnesota 55144 | T7: U.S. | U7: =_xlfn.TEXTJOIN(", ", TRUE, Q7, R7, S7, T7) -> 3M CTR BLDG 201-2E-232, MAPLEWOOD, Minnesota 55144, U.S.
A8: North America | B8: U.S. | C8: EC213486C1 | D8: 3M | E8: 3M | F8: US-Minneapolis | H8: Joel Crespo | I8: Gregory Kleedtke | M8: Guava easyCyte 6HT-2L | N8: NARINA STEPANOVA | O8: nstepanova@mmm.com | Q8: 3M CTR BLDG 201 | R8: MAPLEWOOD | S8: Minnesota 55114 | T8: U.S. | U8: =_xlfn.TEXTJOIN(", ", TRUE, Q8, R8, S8, T8) -> 3M CTR BLDG 201, MAPLEWOOD, Minnesota 55114, U.S.
A9: North America | B9: U.S. | C9: 6735146222 | D9: 3M | E9: 3M | F9: US-Minneapolis | H9: Joel Crespo | I9: Gregory Kleedtke | M9: Guava easyCyte 6HT-2L | N9: JANA NINKOVIC | O9: jninkovic@mmm.com | Q9: 3M CTR BLDG 201-2E-232 | R9: Maplewood | S9: Minnesota 55144 | T9: U.S. | U9: =_xlfn.TEXTJOIN(", ", TRUE, Q9, R9, S9, T9) -> 3M CTR BLDG 201-2E-232, Maplewood, Minnesota 55144, U.S.
A10: North America | B10: U.S. | C10: R1329 | D10: 92Bio Inc | E10: 92BIO | F10: US-Oakland | G10: Stacy Stocki | H10: Carol Oxford | I10: Leland Brasher | J10: 00034590 | K10: Premium | L10: Activated | M10: Cytek Aurora 3 Laser V/B/R - (38 + 3 Channel) | N10: Heather Maecker | O10: hmaecker@ancorabiotech.com | Q10: 1190 Zephyr Ave, Ste A | R10: Hayward | S10: California 94544 | T10: U.S. | U10: =_xlfn.TEXTJOIN(", ", TRUE, Q10, R10, S10, T10) -> 1190 Zephyr Ave, Ste A, Hayward, California 94544, U.S.
A11: North America | B11: U.S. | C11: EC220396F1 | D11: A M TODD | E11: AMTD | I11: Leland Brasher | M11: Guava easyCyte 11HT | N11: JIE LIU | O11: jie.liu@adm.com | Q11: 4091 W 11TH AVE STE E | R11: EUGENE | S11: Oregon 97402 | T11: U.S. | U11: =_xlfn.TEXTJOIN(", ", TRUE, Q11, R11, S11, T11) -> 4091 W 11TH AVE STE E, EUGENE, Oregon 97402, U.S.
A12: North America | B12: U.S. | C12: V0792 | D12: AAT Bioquest | E12: AATB | F12: US-Oakland | G12: Stacy Stocki | H12: Jonathan Paw | I12: Leland Brasher | J12: 00033158 | K12: PMI | L12: Expired | M12: Cytek Aurora 4 Laser UV/V/B/R/ (54 + 3 Channel) | N12: Helen Qin Zhao | O12: helen@aatbio.com | Q12: 5775 W. Las Positas Boulevard | R12: Pleasanton | S12: California 94588 | T12: U.S. | U12: =_xlfn.TEXTJOIN(", ", TRUE, Q12, R12, S12, T12) -> 5775 W. Las Positas Boulevard, Pleasanton, California 94588, U.S.
A13: North America | B13: U.S. | C13: R0732 | D13: abata THERAPEUTICS | E13: ABATA | F13: US-Boston | G13: James Martin | H13: Mark Stottlemyer | I13: Lindsay Albert | M13: Cytek Aurora 3 Laser V/B/R - (38 + 3 Channel) | N13: Juliana Barrios | O13: jbarrios@abatatx.com | Q13: 100 Forge Street (2nd Floor) | R13: Watertown | S13: Massachusetts 02472 | T13: U.S. | U13: =_xlfn.TEXTJOIN(", ", TRUE, Q13, R13, S13, T13) -> 100 Forge Street (2nd Floor), Watertown, Massachusetts 02472, U.S.
A14: North America | B14: U.S. | C14: N0416 | D14: AbboMax, Inc. | E14: ABMX | F14: US-Sacramento | G14: Aldrin Aragon | H14: Jonathan Paw | I14: Leland Brasher | J14: 00012556 | K14: Warranty | L14: Expired | M14: Cytek Northern Lights 3000 V/B/R - (38 + 3 channel) | N14: Kelly Y. Zhou M.D., Ph.D | O14: kellyz@abbomax.com | Q14: 2528 Qume Drive | R14: San Jose | S14: California 95131 | T14: U.S. | U14: =_xlfn.TEXTJOIN(", ", TRUE, Q14, R14, S14, T14) -> 2528 Qume Drive, San Jose, California 95131, U.S.
A15: North America | B15: U.S. | C15: U1611 | D15: AbbVie Inc - AbbVie Bioresearch Center | E15: ABBV | F15: US-Boston | G15: Ilya Permyakov | H15: Mark Stottlemyer | I15: Lindsay Albert | J15: 00036473 | K15: Premium | L15: Activated | M15: Cytek Aurora 5 Laser UV/V/B/YG/R (64 + 3 Channel) | N15: Bit Na Kang | O15: bitna.kang@abbvie.com | Q15: 100 Research Drive | R15: Worcester | S15: Massachusetts 01605 | T15: U.S. | U15: =_xlfn.TEXTJOIN(", ", TRUE, Q15, R15, S15, T15) -> 100 Research Drive, Worcester, Massachusetts 01605, U.S.
A16: North America | B16: U.S. | C16: U1309 | D16: AbbVie Inc - AbbVie Bioresearch Center | E16: ABBV | F16: US-Boston | G16: Ilya Permyakov | H16: Mark Stottlemyer | I16: Lindsay Albert | J16: 00035224 | K16: Premium | L16: Activated | M16: Cytek Aurora 5 Laser UV/V/B/YG/R (64 + 3 Channel) | N16: Zachary Niziolek | O16: zachary.niziolek@abbvie.com | Q16: 100 Research Drive | R16: Worcester | S16: Massachusetts 01605 | T16: U.S. | U16: =_xlfn.TEXTJOIN(", ", TRUE, Q16, R16, S16, T16) -> 100 Research Drive, Worcester, Massachusetts 01605, U.S.
A17: North America | B17: U.S. | C17: ISX440 | D17: AbbVie Inc - AbbVie Bioresearch Center | E17: ABBV | F17: US-Boston | G17: Ilya Permyakov | H17: Mark Stottlemyer | I17: Lindsay Albert | J17: 00035298 | K17: SLA-ISXMKII-COMPLETE | L17: Activated | M17: ImageStreamX MkII Instrument | N17: AXEL HERNANDEZ | O17: axel.hernandezjr@abbvie.com | Q17: 381 PLANTATION ST BIOTECH 5 | R17: WORCESTER | S17: Massachusetts 01605 | T17: U.S. | U17: =_xlfn.TEXTJOIN(", ", TRUE, Q17, R17, S17, T17) -> 381 PLANTATION ST BIOTECH 5, WORCESTER, Massachusetts 01605, U.S.
A18: North America | C18: XF1002 | D18: AbbVie Inc - AbbVie Bioresearch Center | E18: ABBV | G18: Ilya Permyakov | H18: Mark Stottlemyer | I18: Lindsay Albert | J18: 00036967 | K18: Premium | L18: Activated | M18: Cytek Aurora? Evo 5L UV/V/B/YG/R | N18: Bit Na Kang | O18: bitna.kang@abbvie.com | Q18: Precision Medicine Immunology Translational Research 830 Winter Street | R18: Waltham | S18: Massachusetts 02451 | T18: U.S. | U18: =_xlfn.TEXTJOIN(", ", TRUE, Q18, R18, S18, T18) -> Precision Medicine Immunology Translational Research 830 Winter Street, Waltham, Massachusetts 02451, U.S.
A19: North America | C19: U1741 | D19: AbbVie Inc - AbbVie Bioresearch Center | E19: ABBV | F19: US-Boston | G19: Ilya Permyakov | H19: Mark Stottlemyer | I19: Lindsay Albert | J19: 00035019 | K19: Warranty | L19: Activated | M19: Cytek Aurora 5 Laser UV/V/B/YG/R (64 + 3 Channel) | N19: Woojong Lee | O19: woojong.lee@abbvie.com | Q19: 830 Winter Street | R19: Waltham | S19: Massachusetts 02451 | T19: U.S. | U19: =_xlfn.TEXTJOIN(", ", TRUE, Q19, R19, S19, T19) -> 830 Winter Street, Waltham, Massachusetts 02451, U.S.
A20: North America | C20: SM1012 | D20: AbbVie Inc - AbbVie Bioresearch Center | E20: ABBV | F20: US-Boston | G20: Ilya Permyakov | H20: Mark Stottlemyer | I20: Lindsay Albert | J20: 00036524 | K20: Warranty | L20: Activated | M20: Cytek Northern Lights 3000 V/B/R - (38 + 3 channel) | N20: Racheal Akwii | O20: racheal.akwii@abbvie.com | Q20: 381 Plantation Street | R20: Worcester | S20: Massachusetts 01605 | T20: U.S. | U20: =_xlfn.TEXTJOIN(", ", TRUE, Q20, R20, S20, T20) -> 381 Plantation Street, Worcester, Massachusetts 01605, U.S.
A21: North America | C21: NM1678 | D21: AbbVie Inc - AbbVie Bioresearch Center | E21: ABBV | F21: US-Boston | G21: Ilya Permyakov | H21: Mark Stottlemyer | I21: Lindsay Albert | J21: 00036242 | K21: Warranty | L21: Activated | M21: Cytek Northern Lights 3000 V/B/R - (38 + 3 channel) | N21: Cassie Liu | O21: cassie.liu@abbvie.com | Q21: 100 Research Drive | R21: Worcester | S21: Massachusetts 01605 | T21: U.S. | U21: =_xlfn.TEXTJOIN(", ", TRUE, Q21, R21, S21, T21) -> 100 Research Drive, Worcester, Massachusetts 01605, U.S.
A22: North America | B22: U.S. | C22: Y0090 | D22: AbbVie Inc - Bay Area | E22: ABBV | F22: US-San Francisco | G22: Aldrin Aragon | H22: Jonathan Paw | I22: Leland Brasher | J22: 00035179 | K22: Premium | L22: Activated | M22: Cytek Aurora 5 Laser UV/V/B/YG/R (64 + 3 Channel) | N22: Devika Ashok | O22: devika.ashok@abbvie.com | Q22: 05-580 1000 Gateway Blvd | R22: South San Francisco | S22: California 94080 | T22: U.S. | U22: =_xlfn.TEXTJOIN(", ", TRUE, Q22, R22, S22, T22) -> 05-580 1000 Gateway Blvd, South San Francisco, California 94080, U.S.
A23: North America | B23: U.S. | C23: V0350 | D23: AbbVie Inc - Bay Area | E23: ABBV | F23: US-San Francisco | G23: Aldrin Aragon | H23: Jonathan Paw | I23: Leland Brasher | J23: 00035175 | K23: Value | L23: Activated | M23: Cytek Aurora 4 Laser UV/V/B/R/ (54 + 3 Channel) | N23: Claudia Bispo | O23: claudia.bispo@abbvie.com | Q23: 1000 Gateway Blvd Lab 03-590 | R23: South San Francisco | S23: California 94080 | T23: U.S. | U23: =_xlfn.TEXTJOIN(", ", TRUE, Q23, R23, S23, T23) -> 1000 Gateway Blvd Lab 03-590, South San Francisco, California 94080, U.S.
A24: North America | B24: U.S. | C24: V0252 | D24: AbbVie Inc - Bay Area | E24: ABBV | F24: US-San Francisco | G24: Aldrin Aragon | H24: Jonathan Paw | I24: Leland Brasher | J24: 00035177 | K24: Premium | L24: Activated | M24: Cytek Aurora 5 Laser UV/V/B/YG/R (64 + 3 Channel) | N24: Devika Ashok | O24: devika.ashok@abbvie.com | Q24: 1000 Gateway Blvd 5th Floor room#580 | R24: South San Francisco | S24: California 94080 | T24: U.S. | U24: =_xlfn.TEXTJOIN(", ", TRUE, Q24, R24, S24, T24) -> 1000 Gateway Blvd 5th Floor room#580, South San Francisco, California 94080, U.S.
A25: North America | B25: U.S. | C25: U1148 | D25: AbbVie Inc - Bay Area | E25: ABBV | F25: US-San Francisco | G25: Aldrin Aragon | H25: Jonathan Paw | I25: Leland Brasher | J25: 00035180 | K25: Value | L25: Activated | M25: Cytek Aurora 5 Laser UV/V/B/YG/R (64 + 3 Channel) | N25: Claudia Bispo | O25: claudia.bispo@abbvie.com | Q25: 1000 Gateway Blvd Claudia Bispo Lab 03-590 | R25: South San Francisco | S25: California 94080 | T25: U.S. | U25: =_xlfn.TEXTJOIN(", ", TRUE, Q25, R25, S25, T25) -> 1000 Gateway Blvd Claudia Bispo Lab 03-590, South San Francisco, California 94080, U.S.
A26: North America | B26: U.S. | C26: U0557 | D26: AbbVie Inc - Bay Area | E26: ABBV | F26: US-San Francisco | G26: Aldrin Aragon | H26: Jonathan Paw | I26: Leland Brasher | J26: 00035178 | K26: Premium | L26: Activated | M26: Cytek Aurora 5 Laser UV/V/B/YG/R (64 + 3 Channel) | N26: Claudia Bispo | O26: claudia.bispo@abbvie.com | Q26: 03-590Â 1000 Gateway Blvd | R26: South San Francisco | S26: California 94080 | T26: U.S. | U26: =_xlfn.TEXTJOIN(", ", TRUE, Q26, R26, S26, T26) -> 03-590Â 1000 Gateway Blvd, South San Francisco, California 94080, U.S.
A27: North America | C27: 6735145217 | D27: AbbVie Inc - Bay Area | E27: ABBV | G27: Aldrin Aragon | H27: Jonathan Paw | I27: Leland Brasher | N27: JASON BAKER | O27: jason.baker@abbvie.com | U27: =_xlfn.TEXTJOIN(", ", TRUE, Q27, R27, S27, T27)
A28: North America | B28: U.S. | C28: U1372 | D28: AbbVie Inc - Cambridge MA | E28: ABBV | F28: US-Boston | G28: Ilya Permyakov | H28: Mark Stottlemyer | I28: Lindsay Albert | J28: 00036234 | K28: Warranty | L28: Activated | M28: Cytek Aurora 5 Laser UV/V/B/YG/R (64 + 3 Channel) - REFURBISHED | N28: Abeer Obaid | O28: abeer.obaid@abbvie.com | P28: Demo unit U1372 sold to AbbVie Inc in Cambridge, MA. SO.HQ42438 | Q28: 200 Sidney Street | R28: Cambridge | S28: Massachusetts 02139 | T28: U.S. | U28: =_xlfn.TEXTJOIN(", ", TRUE, Q28, R28, S28, T28) -> 200 Sidney Street, Cambridge, Massachusetts 02139, U.S.
A29: North America | B29: U.S. | C29: U0656 | D29: AbbVie Inc - Cambridge MA | E29: ABBV | F29: US-Boston | G29: Ilya Permyakov | H29: Mark Stottlemyer | I29: Lindsay Albert | J29: 00036385 | K29: Premium | L29: Activated | M29: Cytek Aurora 5 Laser UV/V/B/YG/R (64 + 3 Channel) | N29: Nick Hawrylciw | O29: nick.hawrylciw@thermofisher.com | Q29: 40 Guest St | R29: Boston | S29: Massachusetts 02135 | T29: U.S. | U29: =_xlfn.TEXTJOIN(", ", TRUE, Q29, R29, S29, T29) -> 40 Guest St, Boston, Massachusetts 02135, U.S.
A30: North America | B30: U.S. | C30: S0103 | D30: AbbVie Inc - Cambridge MA | E30: ABBV | F30: US-Boston | G30: Ilya Permyakov | H30: Mark Stottlemyer | I30: Lindsay Albert | J30: 00036384 | K30: Premium | L30: Activated | M30: Cytek Aurora-CS 5L System | N30: Khadir Raddassi | O30: khadir.raddassi@abbvie.com | Q30: 40 Guest Street | R30: Boston | S30: Massachusetts 02135 | T30: U.S. | U30: =_xlfn.TEXTJOIN(", ", TRUE, Q30, R30, S30, T30) -> 40 Guest Street, Boston, Massachusetts 02135, U.S.
A31: North America | B31: U.S. | C31: ISX725 | D31: AbbVie Inc - Irvine CA | E31: ABBV | F31: US-Burbank | H31: Aric Bitton | I31: Robert Thacker | J31: 00029470 | K31: SLA-ISXMKII-COMPLETE | L31: Expired | M31: ImageStreamX MkII Instrument | N31: Rob Thacker | O31: rthacker@cytekbio.com | Q31: 2525 Dupont Ave | R31: Irvine | S31: California 92612 | T31: U.S. | U31: =_xlfn.TEXTJOIN(", ", TRUE, Q31, R31, S31, T31) -> 2525 Dupont Ave, Irvine, California 92612, U.S.
A32: North America | B32: U.S. | C32: U1130 | D32: AbbVie Inc - North Chicago | E32: ABBV | F32: US-Chicago | G32: Maria Stanslaski | H32: Joel Crespo | I32: Karen Young | J32: 00035010 | K32: Premium | L32: Activated | M32: Cytek Aurora 5 Laser UV/V/B/YG/R (64 + 3 Channel) | N32: Marion Refici | O32: marion.refici@abbvie.com | Q32: GPRD Stockroom AP9 1 North Waukegan Rd | R32: North Chicago | S32: Illinois 60064 | T32: U.S. | U32: =_xlfn.TEXTJOIN(", ", TRUE, Q32, R32, S32, T32) -> GPRD Stockroom AP9 1 North Waukegan Rd, North Chicago, Illinois 60064, U.S.
A33: North America | B33: U.S. | C33: U0647 | D33: AbbVie Inc - North Chicago | E33: ABBV | F33: US-Chicago | G33: Maria Stanslaski | H33: Joel Crespo | I33: Karen Young | J33: 00035238 | K33: Premium | L33: Activated | M33: Cytek Aurora 5 Laser UV/V/B/YG/R (64 + 3 Channel) | N33: Ryan Duggan | O33: ryan.duggan@abbvie.com | Q33: 1 North Waukegan Road AP9 â?? 1 â?? 1601 | R33: North Chicago | S33: Illinois 60064 | T33: U.S. | U33: =_xlfn.TEXTJOIN(", ", TRUE, Q33, R33, S33, T33) -> 1 North Waukegan Road AP9 â?? 1 â?? 1601, North Chicago, Illinois 60064, U.S.
A34: North America | B34: U.S. | C34: U0277 | D34: AbbVie Inc - North Chicago | E34: ABBV | F34: US-Chicago | G34: Maria Stanslaski | H34: Joel Crespo | I34: Karen Young | J34: 00036186 | K34: Premium | L34: Activated | M34: Cytek Aurora 5 Laser UV/V/B/YG/R (64 + 3 Channel) | N34: Loren Lasko | O34: loren.lasko@abbvie.com | Q34: 1 North Waukegan Rd,Rm AP9-1601 | R34: North Chicago | S34: Illinois 60064 | T34: U.S. | U34: =_xlfn.TEXTJOIN(", ", TRUE, Q34, R34, S34, T34) -> 1 North Waukegan Rd,Rm AP9-1601, North Chicago, Illinois 60064, U.S.
A35: North America | B35: U.S. | C35: ISX433 | D35: AbbVie Inc - North Chicago | E35: ABBV | F35: US-Chicago | G35: Maria Stanslaski | H35: Joel Crespo | I35: Karen Young | J35: 00035244 | K35: SLA-ISXMKII-COMPLETE | L35: Activated | M35: ImageStreamX MkII Instrument | N35: SHAMIM KHAJA | O35: shamim.khaja@abbvie.com | Q35: 1 N Waukegan Rd Bldg AP9 Lab 1310 | R35: North Chicago | S35: Illinois 60044 | T35: U.S. | U35: =_xlfn.TEXTJOIN(", ", TRUE, Q35, R35, S35, T35) -> 1 N Waukegan Rd Bldg AP9 Lab 1310, North Chicago, Illinois 60044, U.S.
A36: North America | B36: U.S. | C36: N0136 | D36: ABBVsion | E36: ABVIS | F36: US-Sacramento | G36: Aldrin Aragon | H36: Jonathan Paw | I36: Leland Brasher | J36: 00013234 | K36: Premium | L36: Expired | M36: Cytek Northern Lights 3000 V/B/R - (38 + 3 channel) | Q36: 2528 Qume Drive, Suite 12 | R36: San Jose | S36: California 95131 | T36: U.S. | U36: =_xlfn.TEXTJOIN(", ", TRUE, Q36, R36, S36, T36) -> 2528 Qume Drive, Suite 12, San Jose, California 95131, U.S.
A37: North America | B37: U.S. | C37: EC213266H1 | D37: Abcam Inc | E37: ABCM | F37: US-Boston | H37: Mark Stottlemyer | I37: Lindsay Albert | J37: 00026318 | K37: SLA-EC-INTERMED | L37: Expired | M37: Guava easyCyte 12HT | N37: IZZUDDIN DIWAN | O37: izzuddin.diwan@abcam.com | Q37: 152 GROVE ST STE 1100 | R37: WALTHAM | S37: Massachusetts 02453 | T37: U.S. | U37: =_xlfn.TEXTJOIN(", ", TRUE, Q37, R37, S37, T37) -> 152 GROVE ST STE 1100, WALTHAM, Massachusetts 02453, U.S.
A38: North America | B38: U.S. | C38: EC211336C1 | D38: Abcam Inc | E38: ABCM | F38: US-Boston | H38: Mark Stottlemyer | I38: Lindsay Albert | M38: Guava easyCyte 6HT-2L | N38: IZZUDDIN DIWAN | O38: izzuddin.diwan@abcam.com | Q38: 152 GROVE ST | R38: WALTHAM | S38: Massachusetts 02139 | T38: U.S. | U38: =_xlfn.TEXTJOIN(", ", TRUE, Q38, R38, S38, T38) -> 152 GROVE ST, WALTHAM, Massachusetts 02139, U.S.
A39: North America | B39: U.S. | C39: 8470060215 | D39: Abcam Inc | E39: ABCM | F39: US-Boston | H39: Mark Stottlemyer | I39: Lindsay Albert | M39: Guava easyCyte 6HT-2L | N39: IZZUDDIN DIWAN | O39: izzuddin.diwan@abcam.com | Q39: 152 GROVE ST | R39: WALTHAM | S39: Massachusetts 02139 | T39: U.S. | U39: =_xlfn.TEXTJOIN(", ", TRUE, Q39, R39, S39, T39) -> 152 GROVE ST, WALTHAM, Massachusetts 02139, U.S.
A40: North America | B40: U.S. | C40: 8470060130 | D40: Abcam Inc | E40: ABCM | F40: US-Boston | H40: Mark Stottlemyer | I40: Lindsay Albert | M40: Guava easyCyte 6HT-2L | N40: IZZUDDIN DIWAN | O40: izzuddin.diwan@abcam.com | Q40: 152 GROVE ST STE 1100 | R40: WALTHAM | S40: Massachusetts 02453 | T40: U.S. | U40: =_xlfn.TEXTJOIN(", ", TRUE, Q40, R40, S40, T40) -> 152 GROVE ST STE 1100, WALTHAM, Massachusetts 02453, U.S.
...

Sheet Pricing Data
A1: Display Name | B1: Last Purchase Price | C1: Sale Unit | D1: Unit Price | E1: Price Level | F1: Currency | G1: Part Number | H1: Item Internal ID
A2: Value contract deductible | D2: 750 | F2: US Dollar | G2: Value
A3: On-Site Support (2 days) | D3: 7571 | F3: US Dollar | G3: 60020
A4: Basic contract deductible | F4: US Dollar
A5: Vacuum Manifold | B5: 58.56 | C5: Each | D5: 274.64 | E5: List Price | F5: US Dollar | G5: N0-00001 | H5: 34749
A6: Mounting Plate | B6: 2.12 | C6: Each | D6: 7.76 | E6: List Price | F6: US Dollar | G6: N0-00002 | H6: 16742
A7: Valve Guide | B7: 7.46 | C7: Each | D7: 22.38 | E7: List Price | F7: US Dollar | G7: N0-00003 | H7: 16743
A8: Pinch Hammer | B8: 0 | C8: Each | D8: 33.57 | E8: List Price | F8: US Dollar | G8: N0-00004 | H8: 16744
A9: Pinch Head | B9: 0 | C9: Each | D9: 80.61 | E9: List Price | F9: US Dollar | G9: N0-00005 | H9: 16745
A10: DeGasser Bracket | B10: 3.34 | C10: Each | D10: 12.53 | E10: List Price | F10: US Dollar | G10: N0-00006 | H10: 16746
A11: Lens Retaining Cover | B11: 3.6 | C11: Each | D11: 37.38 | E11: List Price | F11: US Dollar | G11: N0-00009 | H11: 16747
A12: Lens Barrel | B12: 21.81 | C12: Each | D12: 141.56 | E12: List Price | F12: US Dollar | G12: N0-00010 | H12: 16748
A13: Flow Cell Body | B13: 114.06 | C13: Each | D13: 268.71 | E13: List Price | F13: US Dollar | G13: N0-00011 | H13: 16752
A14: Flow Cell Exit | B14: 20.57 | C14: Each | D14: 53.73 | E14: List Price | F14: US Dollar | G14: N0-00012 | H14: 16753
A15: SIT Base | B15: 12.69 | C15: Each | D15: 38.07 | E15: List Price | F15: US Dollar | G15: N0-00013 | H15: 16754
A16: Red Prism Block | B16: 11.49 | C16: Each | D16: 57.09 | E16: List Price | F16: US Dollar | G16: N0-00014 | H16: 16757
... A1085: 0.07" EPDM O-ring Cord Stock | B1085: 0.27 | C1085: Foot | D1085: 0.02461 | E1085: List Price | F1085: US Dollar | G1085: N4-00095 | H1085: 75631
A1087: MMC 9616K11
A1088: O-RING, AS568A-159, EPDM 70 DURO | B1088: 12.16 | C1088: Each | D1088: 0.48 | E1088: List Price | F1088: US Dollar | G1088: N4-00100 | H1088: 15287
A1089: 1/4-28 x 1/8 FEMALE Luer BARB PANEL MT | B1089: 0.57 | C1089: Each | D1089: 1.52 | E1089: List Price | F1089: US Dollar | G1089: N4-00104 | H1089: 15319
A1090: Tee Tube Fitting with Classic Series Barbs, 1/8" (3.2 | B1090: 1.04 | C1090: Each | D1090: 2.67 | E1090: List Price | F1090: US Dollar | G1090: N4-00105 | H1090: 15339
A1091: Aria 1/32" Ferrule for PEEK Tubing in PMI Kit | B1091: 2 | C1091: Each | D1091: 9.21 | E1091: List Price | F1091: US Dollar | G1091: N4-00106 | H1091: 15342
A1092: ALMOND BULKHEAD 1/8" | B1092: 7.91 | C1092: Each | D1092: 41.91 | E1092: List Price | F1092: US Dollar | G1092: N4-00107 | H1092: 15370
A1093: FEMALE 1/4 NPT COLDER | B1093: 6.47 | C1093: Each | D1093: 29.43 | E1093: List Price | F1093: US Dollar | G1093: N4-00112 | H1093: 15373
A1094: ALMOND MALE COLDER 1/8" | B1094: 5.51 | C1094: Each | D1094: 18.33 | E1094: List Price | F1094: US Dollar | G1094: N4-00114 | H1094: 15376
A1095: ORG MALE COLDER 1/8" | B1095: 7.05 | C1095: Each | D1095: 18.33 | E1095: List Price | F1095: US Dollar | G1095: N4-00116 | H1095: 49212
A1096: SHEATH LEVEL SENSOR CAP | B1096: 3.56 | C1096: Each | D1096: 46.68 | E1096: List Price | F1096: US Dollar | G1096: N4-00118 | H1096: 15485
A1097: NC FLOAT SWITCH Brown Wires | B1097: 35.74 | C1097: Each | D1097: 94.74 | E1097: List Price | F1097: US Dollar | G1097: N4-00120 | H1097: 15490
A1098: Pressure Transducer Athena/Rainbow | B1098: 48.99 | C1098: Each | D1098: 183 | E1098: List Price | F1098: US Dollar | G1098: N4-00122 | H1098: 15567
A1099: 4L Tank | B1099: 126.9 | C1099: Each | D1099: 137.22 | E1099: List Price | F1099: US Dollar | G1099: N4-00124 | H1099: 15568
... A2662: RYV Upgrade (Monthly) | B2662: 0 | C2662: Each | D2662: 525 | E2662: List Price | F2662: US Dollar | G2662: N9-90097 | H2662: 105652
A2663: OQ Package (2PM visits) | B2663: 0 | D2663: 10500 | E2663: List Price | F2663: US Dollar | G2663: N9-90099 | H2663: 68075
A2664: OQ Package (All service visits) | B2664: 0 | D2664: 15750 | E2664: List Price | F2664: US Dollar | G2664: N9-90100 | H2664: 68076
A2665: IQ/OQ | B2665: 0 | D2665: 10500 | E2665: List Price | F2665: US Dollar | G2665: N9-90101 | H2665: 22353
A2666: Annual Surcharge | B2666: 0 | C2666: Each | D2666: 1313 | E2666: List Price | F2666: US Dollar | G2666: N9-90102 | H2666: 65838
A2667: Quarterly Surcharge | B2667: 0 | C2667: Each | D2667: 2625 | E2667: List Price | F2667: US Dollar | G2667: N9-90103 | H2667: 65839
A2668: BSL3/4 Surcharge | B2668: 0 | C2668: Each | D2668: 10500 | E2668: List Price | F2668: US Dollar | G2668: N9-90104 | H2668: 109579
A2669: BSL3/4 Surcharge | B2669: 0 | C2669: Each | D2669: 10000 | E2669: List Price | F2669: US Dollar | G2669: N9-90104-INA | H2669: 65840
A2670: Priority Response | B2670: 0 | C2670: Each | D2670: 1575 | E2670: List Price | F2670: US Dollar | G2670: N9-90105 | H2670: 20180
A2671: Cytek Spectral Cytometry Additional Training Provisions | B2671: 0 | C2671: Each | D2671: 5516 | E2671: List Price | F2671: US Dollar | G2671: N9-90106 | H2671: 68301
...

Sheet Cytek Service Quoting Old
C2: ='FSE Input Old'!A3 -> Brad Ballard | F2: ="QUOTE#: "&'FSE Input Old'!$D$3&" "&'FSE Input Old'!$B$3 -> QUOTE#: MSU U0286
C3: ='FSE Input Old'!C3 -> Michigan State University
C4: ='FSE Input Old'!E3 -> 775 Woodlot Dr Bioengineering/IQ Building Rm 2315, East Lansing, Michigan 48824, U.S.
C7: Item | D7: Description | E7: Product Number | F7: Qty | G7: List Price | H7: Net Price | I7: Ext. Price
C8: =IF(D8="", "", "1") -> 1 | D8: =IF('FSE Input Old'!A7<>"", 'FSE Input Old'!A7, IF('FSE Input Old'!E7<>"", 'FSE Input Old'!E7, "")) -> On-Site Support (2 days) | E8: =IF('FSE Input Old'!B7<>"", 'FSE Input Old'!B7, IF('FSE Input Old'!F7<>"", 'FSE Input Old'!F7, "")) -> 60020 | F8: =IF(ISBLANK('FSE Input Old'!D7),"",'FSE Input Old'!D7) -> 1 | G8: =IF('FSE Input Old'!C7<>"", 'FSE Input Old'!C7, IF('FSE Input Old'!G7<>"", 'FSE Input Old'!G7, "")) -> 7571 | H8: =IF(G8="", "", IF(ISNUMBER(SEARCH("on-site", D8)), G8, IF(ISNUMBER(SEARCH("basic", 'FSE Input Old'!F$3)), G8*0.9, IF(ISNUMBER(SEARCH("value", 'FSE Input Old'!F$3)), G8-750, "") ) ) ) -> 7571 | I8: =IF(G8="","",H8*F8) -> 7571
C9: =IF(D9="", "", "2") -> 2 | D9: =IF('FSE Input Old'!A8<>"", 'FSE Input Old'!A8, IF('FSE Input Old'!E8<>"", 'FSE Input Old'!E8, "")) -> guava eacyCyte HT Preventative Maintenance | E9: =IF('FSE Input Old'!B8<>"", 'FSE Input Old'!B8, IF('FSE Input Old'!F8<>"", 'FSE Input Old'!F8, "")) -> PM-EASYCYTE-HT | F9: =IF(ISBLANK('FSE Input Old'!D8),"",'FSE Input Old'!D8) -> 1 | G9: =IF('FSE Input Old'!C8<>"", 'FSE Input Old'!C8, IF('FSE Input Old'!G8<>"", 'FSE Input Old'!G8, "")) -> 4814 | H9: =IF(G9="", "", IF(ISNUMBER(SEARCH("on-site", D9)), G9, IF(ISNUMBER(SEARCH("basic", 'FSE Input Old'!F$3)), G9*0.9, IF(ISNUMBER(SEARCH("value", 'FSE Input Old'!F$3)), G9-750, "") ) ) ) -> 4064 | I9: =IF(G9="","",H9*F9) -> 4064
C10: =IF(D10="", "", "3") -> 3 | D10: =IF('FSE Input Old'!A9<>"", 'FSE Input Old'!A9, IF('FSE Input Old'!E9<>"", 'FSE Input Old'!E9, "")) -> Sheath Filter, Rainbow | E10: =IF('FSE Input Old'!B9<>"", 'FSE Input Old'!B9, IF('FSE Input Old'!F9<>"", 'FSE Input Old'!F9, "")) -> N4-00025 | F10: =IF(ISBLANK('FSE Input Old'!D9),"",'FSE Input Old'!D9) -> 1 | G10: =IF('FSE Input Old'!C9<>"", 'FSE Input Old'!C9, IF('FSE Input Old'!G9<>"", 'FSE Input Old'!G9, "")) -> 192.45 | H10: =IF(G10="", "", IF(ISNUMBER(SEARCH("on-site", D10)), G10, IF(ISNUMBER(SEARCH("basic", 'FSE Input Old'!F$3)), G10*0.9, IF(ISNUMBER(SEARCH("value", 'FSE Input Old'!F$3)), G10-750, "") ) ) ) -> -557.55 | I10: =IF(G10="","",H10*F10) -> -557.55
C11: =IF(D11="", "", "4") | D11: =IF('FSE Input Old'!A10<>"", 'FSE Input Old'!A10, IF('FSE Input Old'!E10<>"", 'FSE Input Old'!E10, "")) | E11: =IF('FSE Input Old'!B10<>"", 'FSE Input Old'!B10, IF('FSE Input Old'!F10<>"", 'FSE Input Old'!F10, "")) | F11: =IF(ISBLANK('FSE Input Old'!D10),"",'FSE Input Old'!D10) | G11: =IF('FSE Input Old'!C10<>"", 'FSE Input Old'!C10, IF('FSE Input Old'!G10<>"", 'FSE Input Old'!G10, "")) | H11: =IF(G11="", "", IF(ISNUMBER(SEARCH("on-site", D11)), G11, IF(ISNUMBER(SEARCH("basic", 'FSE Input Old'!F$3)), G11*0.9, IF(ISNUMBER(SEARCH("value", 'FSE Input Old'!F$3)), G11-750, "") ) ) ) | I11: =IF(G11="","",H11*F11)
C13: Shipping & Handling Estimate
C14: Total | I14: =SUM(I15,I8:I11) -> 11077.45
G49: ="QUOTE#: "&'FSE Input Old'!$D$3&" "&'FSE Input Old'!$B$3 -> QUOTE#: MSU U0286
G101: ="QUOTE#: "&'FSE Input Old'!$D$3&" "&'FSE Input Old'!$B$3 -> QUOTE#: MSU U0286
G153: ="QUOTE#: "&'FSE Input Old'!$D$3&" "&'FSE Input Old'!$B$3 -> QUOTE#: MSU U0286

Sheet FSE Input Old
A1: CUSTOMER INFORMATION
A2: Name of customer requesting service/part: | B2: Instrument SN: | C2: Facility name: | D2: Shortened Facility name (ex. BCH): | E2: Facility Address: | F2: Contract type:
A3: Brad Ballard | B3: U0286 | C3: =VLOOKUP(B3,'Asset Data'!C2:U3586,2,FALSE) -> Michigan State University | D3: =VLOOKUP(C3,'Asset Data'!D1:E3586,2,FALSE) -> MSU | E3: =VLOOKUP(B3,'Asset Data'!C2:U3586,19,FALSE) -> 775 Woodlot Dr Bioengineering/IQ Building Rm 2315, East Lansing, Michigan 48824, U.S. | F3: =VLOOKUP(B3,'Asset Data'!C2:U3586,9,FALSE) -> Value
A5: SERVICE TYPE / PART NAME
A6: Service Type/ Part Name | B6: Service Type/Part Number | C6: Service Type/ Part Price | D6: Quantity | E6: Service Type / Part Name (if not listed) | F6: Service Type Part Number (if not listed) | G6: Price of Service Type / Part (if not listed)
A7: On-Site Support (2 days) | B7: =IF(A7="","",VLOOKUP(A7,'Pricing Data'!A$2:H5436,7,FALSE)) -> 60020 | C7: =IF(A7="","",VLOOKUP(A7,'Pricing Data'!A2:H5436,4,FALSE)) -> 7571 | D7: 1
A8: guava eacyCyte HT Preventative Maintenance | B8: =IF(A8="","",VLOOKUP(A8,'Pricing Data'!A$2:H5437,7,FALSE)) -> PM-EASYCYTE-HT | C8: =IF(A8="","",VLOOKUP(A8,'Pricing Data'!A2:H5437,4,FALSE)) -> 4814 | D8: 1
A9: Sheath Filter, Rainbow | B9: =IF(A9="","",VLOOKUP(A9,'Pricing Data'!A$2:H5438,7,FALSE)) -> N4-00025 | C9: =IF(A9="","",VLOOKUP(A9,'Pricing Data'!A2:H5438,4,FALSE)) -> 192.45 | D9: 1
B10: =IF(A10="","",VLOOKUP(A10,'Pricing Data'!A2:H5439,7,FALSE)) | C10: =IF(A10="","",VLOOKUP(A10,'Pricing Data'!A2:H5439,4,FALSE))
B18: Name of customer requesting service/part: | C18: Brad Ballard | E18: SERVICE TYPE / PART NAME | F18: Service Type/ Part Name | G18: On-Site Support (2 days) | H18: guava eacyCyte HT Preventative Maintenance | I18: Sheath Filter, Rainbow
B19: Instrument SN: | C19: U0286 | F19: Service Type/Part Number | G19: =IF(G18="","",VLOOKUP(G18,'Pricing Data'!$B18:HAB25,7,FALSE)) -> #N/A | H19: =IF(H18="","",VLOOKUP(H18,'Pricing Data'!$B18:HAC25,7,FALSE)) -> #N/A | I19: =IF(I18="","",VLOOKUP(I18,'Pricing Data'!$B18:HAD25,7,FALSE)) -> #N/A | J19: =IF(J18="","",VLOOKUP(J18,'Pricing Data'!B18:HAE25,7,FALSE))
B20: Facility name: | C20: =VLOOKUP(C19,'Asset Data'!B20:EGX38,2,FALSE) -> #N/A | F20: Service Type/ Part Price | G20: =IF(G18="","",VLOOKUP(G18,'Pricing Data'!B18:HAB25,4,FALSE)) -> #N/A | H20: =IF(H18="","",VLOOKUP(H18,'Pricing Data'!B18:HAC25,4,FALSE)) -> #N/A | I20: =IF(I18="","",VLOOKUP(I18,'Pricing Data'!B18:HAD25,4,FALSE)) -> #N/A | J20: =IF(J18="","",VLOOKUP(J18,'Pricing Data'!B18:HAE25,4,FALSE))
B21: Shortened Facility name (ex. BCH): | C21: =VLOOKUP(C20,'Asset Data'!A21:EGX22,2,FALSE) -> #N/A | F21: Quantity | G21: 1 | H21: 1 | I21: 1
B22: Facility Address: | C22: =VLOOKUP(C19,'Asset Data'!B20:EGX38,19,FALSE) -> #N/A | F22: Service Type / Part Name (if not listed)
B23: Contract type: | C23: =VLOOKUP(C19,'Asset Data'!B20:EGX38,9,FALSE) -> #N/A | F23: Service Type Part Number (if not listed)
F24: Price of Service Type / Part (if not listed)
A32: SERVICE TYPE/PART NAME - SERVICE QUOTE
B33: Part 1 | C33: Part 2 | D33: Part 3 | E33: Part 4
A34: Service Type/ Part Name | B34: On-Site Support (2 days) | C34: guava eacyCyte HT Preventative Maintenance | D34: Sheath Filter, Rainbow
A35: Service Type/Part Number | B35: =IF(B34="","",VLOOKUP(B34,'Pricing Data'!$B31:GZX38,7,FALSE)) -> #N/A | C35: =IF(C34="","",VLOOKUP(C34,'Pricing Data'!$B31:GZY38,7,FALSE)) -> #N/A | D35: =IF(D34="","",VLOOKUP(D34,'Pricing Data'!$B31:GZZ38,7,FALSE)) -> #N/A | E35: =IF(E34="","",VLOOKUP(E34,'Pricing Data'!#REF!,7,FALSE))
A36: Service Type/ Part Price | B36: =IF(B34="","",VLOOKUP(B34,'Pricing Data'!#REF!,4,FALSE)) -> #REF! | C36: =IF(C34="","",VLOOKUP(C34,'Pricing Data'!#REF!,4,FALSE)) -> #REF! | D36: =IF(D34="","",VLOOKUP(D34,'Pricing Data'!#REF!,4,FALSE)) -> #REF! | E36: =IF(E34="","",VLOOKUP(E34,'Pricing Data'!#REF!,4,FALSE))
A37: Quantity | B37: 1 | C37: 1 | D37: 1
A38: Service Type / Part Name (if not listed)
A39: Service Type Part Number (if not listed)
A40: Price of Service Type / Part (if not listed)
